Workbook

Sheet 00_Index
A1: PublicLogic Series 1 — Final Workbook Index
A2: Final competitive/positioning update: standing/closing CaseSpaces, non-replacement discipline, stewardship, and battlecards.
A4: Sheet | B4: Purpose | C4: Type
A5: 00_Index | B5: Workbook map and final update notes | C5: Index
A6: 01_Core_Doctrine | B6: Core doctrine updated: primitive + non-replacement + counsel-ready fence | C6: Doctrine
A7: 02_Problems | B7: Problem framing for search, bridges, and human routing | C7: Doctrine
A8: 03_Client_Experience | B8: PJ Lite client experience and promise | C8: Doctrine
A9: 04_CaseSpace_Schema | B9: Standing/closing CaseSpace fields and seed JSON | C9: Build Spec
A10: 05_Series1_Templates | B10: Series 1 ready-to-run template catalog | C10: Product Spec
A11: 06_Work_Packs | B11: Bundles of parent + child CaseSpace templates | C11: Product Spec
A12: 07_Dashboards | B12: Dashboard layers and formulas | C12: Product Spec
A13: 08_Permit_Bridge_Lanes | B13: Permit & Bridge lane model | C13: Product Spec
A14: 09_Doors_Same_System | B14: Proof that all doors map to Capture/Classify/Advance/Seal | C14: Doctrine
A15: 10_Time_Attendance | B15: Time and attendance as a work pack, not HRIS | C15: Product Spec
... A35: 26_Industry_Combos | B35: Which template overlays (vowels) run on the same tools (consonants), by industry | C35: Strategy

Sheet 01_Core_Doctrine
A1: Core Doctrine — One Primitive, Many Surfaces
A2: PublicLogic is a governed work library of templates, tools, and information that open as standing/closing CaseSpaces, backed by stewardship and designed not to replace existing systems.
A4: Decision | B4: Canonical Binding | C4: Meaning | D4: Fence
A5: One Primitive | B5: CaseSpace | C5: A governed operating record for a unit of work. It can be standing/container or closing/leaf. | D5: Doctrine
A6: Standing CaseSpace | B6: Container | C6: Ongoing parent: property, department, project, client, program, app/repo, or operating area. | D6: Doctrine
A7: Closing CaseSpace | B7: Leaf | C7: Finite child: turnover, permit lane, grant submission, release, invoice, incident, policy update, request, or handoff. | D7: Doctrine
A8: Seal-Upward Rule | B8: Closing → Standing | C8: Closing work resolves and seals upward into its standing parent as a referenceable proof package. It does not mutate parent truth. | D8: Moat
A9: Surface-not-State Rule | B9: External tools are signals/surfaces | C9: Email, Drive, PMS, CRM, permitting, grant, and finance systems can inform a CaseSpace. They are not the canonical PJ state. | D9: Moat
A10: Non-Replacement Rule | B10: Do not become their system of record | C10: PublicLogic makes work ready, visible, portable, and provable across systems without asking clients to rip and replace. | D10: Partner-safe
A11: PJ Lite Rule | B11: Smaller at the edge, not smaller in ambition | C11: Client sees Path Sheet, CaseSpace, Next Steps, Record. Runtime language stays behind the curtain. | D11: Client-safe
A12: All Doors Rule | B12: Capture → Classify → Advance → Seal | C12: Every work pack uses the same four-action loop and same CaseSpace recordstream. | D12: Doctrine
A13: Work Library Rule | B13: Templates + tools + information, not products | C13: The library is templates (structures), tools (generators, lane pickers, dashboards), and information (law-aware references). No single work pack — time & attendance included — is the output. | D13: Doctrine
A14: Stewardship Rule | B14: Human-supported library upkeep | C14: PublicLogic maintains templates, handoffs, readiness logic, and continuity records so the system stays usable after launch. | D14: Moat
A15: Counsel-Ready Rule | B15: No legal advice / no determinations | C15: Templates organize facts, rules, documents, deadlines, authority questions, and proof so counsel, officials, staff, or decision-makers can act from a cleaner record. | D15: Legal fence
... A17: Composer Rule | B17: User builds; PublicLogic takes it from there | C17: Users assemble their own experience from templates, tools, and information. PublicLogic stands up the CaseSpace — for a single user or a duo — runs the runtime, and maintains continuity from there. | D17: Moat

Sheet 02_Problems
A1: Permanent Problems — What Every Template Must Fix
A2: The workbook is anchored on two market problems: simpler AI/search paths and no human bridge between every system.
A4: ID | B4: Problem | C4: Observed Signal | D4: Template Requirement | E4: Do Not Build | F4: Proof of Fix
A5: P-001 | B5: Simpler AI / Search Path | C5: Operator should not have to think about SQL, vectors, prompts, or search plumbing. | D5: Template must define searchable fields, record homes, proof events, and retrieval surfaces. | E5: Do not build vague AI layer. | F5: Can retrieve the record and explain what is missing/next.
A6: P-002 | B6: No Human Bridge Between Systems | C6: Operator should not babysit exports, re-key data, or manually glue tools together. | D6: Template must name the manual bridge removed and the CaseSpace event replacing it. | E6: Do not build another dashboard that still requires re-entry. | F6: CaseSpace event replaces handoff/re-entry or makes bridge visible.

Sheet 03_Client_Experience
A1: PJ Lite — The Client Experience
A2: The quiet workbench: PuddleJumper does the governing; the client sees a plain path, documents, what's next, and what was decided.
A4: Section | B4: Doctrine | C4: Client-Safe Meaning
A5: One Rule | B5: Do not sell or explain PJ. Sell the outcome. | C5: We organize the work into one record, show what has to happen next, keep the documents straight, and make sure nothing important gets lost.
A6: Four Questions | B6: What are we trying to get done? What do we know? What is missing? What happens next? | C6: Every client screen should reduce uncertainty.
A7: Client Flow | B7: Intake → Path Sheet → CaseSpace → Next Steps → Record | C7: Same beats for STAY, MUNI, BIZ, GRANT, LIVE, HOME, PEOPLE, and Permit & Bridge.
A8: Client Language | B8: Path Sheet; CaseSpace; Next Steps; Record | C8: No runtime, VAULT, CAL, PRM, Module Maker, governed process spine.
A9: Free Tool Boundary | B9: First-pass Path Sheet only | C9: It says what probably has to be true before this can move. It does not solve the whole matter.
A10: Promise | B10: Nothing gets lost | C10: The client should know where the document is, who owns it, what is next, and what was decided.

Sheet 04_CaseSpace_Schema
A1: CaseSpace Schema — Standing + Closing
A2: Required fields for the same record model behind every door.
A4: Field | B4: Allowed Values | C4: Applies To | D4: Meaning | E4: Requirement | F4: Visibility
A5: case_id | B5: string | C5: closing or standing | D5: Unique CaseSpace identifier | E5: Required | F5: Internal
A6: case_type | B6: standing | closing | C6: both | D6: Proof-axis distinction; standing contains closing children | E6: Required | F6: Doctrine
A7: family | B7: STAY/MUNI/BIZ/GRANT/LIVE/HOME/PEOPLE/OPS/etc. | C7: both | D7: Skin/template family | E7: Required | F7: Client-safe if needed
A8: parent_case_id | B8: string/null | C8: closing | D8: Standing parent for child/leaf cases | E8: Required for closing | F8: Internal
A9: desired_outcome | B9: text | C9: both | D9: What are we trying to get done? | E9: Required | F9: Client
A10: known_facts | B10: array | C10: both | D10: What do we know? | E10: Required | F10: Client
A11: missing_facts | B11: array | C11: both | D11: What is missing? | E11: Required | F11: Client
A12: documents_needed | B12: array | C12: both | D12: Needed documents/evidence | E12: Required | F12: Client
A13: next_steps | B13: array | C13: both | D13: What happens next? | E13: Required | F13: Client
A14: decisions | B14: array | C14: both | D14: What was decided and by whom | E14: Required | F14: Client
A15: proof_events | B15: array | C15: closing | D15: Capture/advance/seal proof events | E15: Required | F15: Internal/client record
... A19: owners | B19: 1-2 authenticated users; scales to team/department | C19: both | D19: Who owns this CaseSpace. Floor is a single user or a duo on one shared CaseSpace — no department required. | E19: Required | F19: Internal

Sheet 05_Series1_Templates
A1: Series 1 Templates — Governed Work Library
A2: The first ready-to-run governed work library. Every template opens a live CaseSpace; none is a replacement product.
A4: ID | B4: Family | C4: Template / Entry | D4: Work Pack | E4: Standing Parent | F4: Closing Children | G4: Primary Use | H4: Capture Triggers | I4: Classify Via | J4: Advance Gate | K4: Seal / Proof Output | L4: Dashboard | M4: Status | N4: Priority | O4: Notes | P4: Track
A5: S1-001 | B5: ALL | C5: Path Sheet Entry | D5: CaseSpace Entry | E5: Matter / Opportunity | F5: Path Sheet; Quick Review | G5: Prospect/client triage | H5: messy facts, docs, links, screenshots | I5: Path Sheet family + risk lanes | J5: Bridge Rating + recommended next step | K5: Path Sheet PDF; CaseSpace seed JSON | L5: Client: Path Sheet; Operator: Intake | M5: Ratified | N5: P0 | O5: Demo first; avoid 'front door' language | P5: Launch Door
A6: S1-002 | B6: MUNI | C6: Permit & Bridge | D6: MUNI Work Pack | E6: Applicant / Site / Project | F6: Lane Review; Missing Fact; Agency Question; Draft Filing | G6: Municipal/project readiness | H6: parcel, use, authority, docs, deadlines | I6: permit/board/agency lanes | J6: lane gate + authority check | K6: Path Sheet; Bridge Package; submission record | L6: Permit dashboard | M6: Ratified | N6: P0 | O6: Readiness only; not permitting software | P6: Launch Door
A7: S1-003 | B7: GRANT | C7: Grant Readiness | D7: GRANT Work Pack | E7: Opportunity / Program | F7: Eligibility; Match; Partner; Budget; Narrative; Submission | G7: Grant before grant management | H7: NOFO, budget, partners, commitments | I7: eligibility + authority + evidence | J7: submission readiness gate | K7: application packet + submission proof | L7: Grant dashboard | M7: Ratified | N7: P0 | O7: Strong PublicLogic lane | P7: Launch Door
A8: S1-004 | B8: STAY | C8: Property Memory | D8: STAY Work Pack | E8: Property | F8: Guest Stay; Turnover; Maintenance; Incident; Receipt | G8: Short-term-rental owner ops | H8: booking, cleaner, vendor, guest, receipts | I8: property + event type | J8: occupied/clean/repair conflict check | K8: turnover proof; incident/maintenance record | L8: STAY dashboard | M8: Ratified | N8: P0 | O8: Kendall Pond proof lane; not PMS | P8: Launch Door
A9: S1-005 | B9: MUNI/BIZ | C9: Policy / SOP Stewardship | D9: Continuity Work Pack | E9: Department / Process | F9: Policy Change; SOP Update; Training; Acknowledgment | G9: Continuity and implementation support | H9: drafts, decisions, staff notes | I9: policy/process + owner | J9: approval/ratification gate | K9: ratified policy/SOP record | L9: Continuity dashboard | M9: Ratified | N9: P0 | O9: Moved up: core stewardship moat | P9: Launch Door
A10: S1-006 | B10: ALL | C10: Quick Review | D10: PJ Lite Service | E10: Matter / Opportunity | F10: Document Review; Call Notes; Decision | G10: Prospect to paid review | H10: submitted docs + open questions | I10: family/skin + missing facts | J10: review call + scope boundary | K10: sharper Path Sheet; call summary | L10: Client: Next Steps | M10: Ratified | N10: P0 | O10: Service-led | P10: Service Lane
A11: S1-007 | B11: ALL | C11: Bridge Package | D11: PJ Lite Service | E11: Matter / Opportunity | F11: Docs; Draft Correspondence; Timeline; Parties | G11: Readiness package | H11: client docs, agency/vendor inputs | I11: lanes + responsible parties | J11: proof checklist + send gate | K11: organized readiness packet | L11: Client: Documents/Decisions | M11: Ratified | N11: P0 | O11: Revenue lane | P11: Service Lane
A12: S1-008 | B12: ALL | C12: Live CaseSpace | D12: PJ Lite Service | E12: Standing Matter | F12: Weekly Update; Child Cases; Decisions | G12: Ongoing managed work | H12: ongoing signals, decisions, docs | I12: standing + child CaseSpaces | J12: CAL/PRM-gated next move | K12: sealed child records + rollup | L12: Client: five tabs; Operator: movement board | M12: Ratified | N12: P0 | O12: Core paid experience | P12: Service Lane
A13: S1-009 | B13: PEOPLE | C13: Time & Attendance | D13: Workforce Work Pack | E13: Department / Crew / Project | F13: Shift; Timesheet; Leave; Overtime; Training; Incident | G13: Small team / municipal / property crew | H13: clock, schedule, leave, supervisor notes | I13: person + role + time window | J13: supervisor approval + payroll export gate | K13: approved timesheet + audit record | L13: People dashboard | M13: Ratified | N13: P1 | O13: Template, not HRIS product | P13: Extended
A14: S1-010 | B14: MUNI | C14: Public Records / Board Packet | D14: MUNI Work Pack | E14: Department / Board | F14: Request; Document; Review; Redaction; Packet Item | G14: Municipal record discipline | H14: email, forms, agendas, attachments | I14: record type + deadline | J14: authority/deadline check | K14: response proof; packet proof | L14: MUNI dashboard | M14: Ratified | N14: P1 | O14: Avoid public records system replacement | P14: Extended
A15: S1-011 | B15: BIZ | C15: Client Deliverable | D15: BIZ Work Pack | E15: Client / Project | F15: Task; Draft; Decision; Invoice; Handoff | G15: Consulting ops | H15: emails, docs, meetings, drafts | I15: deliverable + deadline + owner | J15: ready-to-send gate | K15: sent deliverable + proof | L15: BIZ dashboard | M15: Ratified | N15: P1 | O15: Immediate internal use | P15: Extended
... A20: S1-016 | B20: PEOPLE | C20: Hiring / Onboarding | D20: Workforce Work Pack | E20: Department / Role | F20: Posting; Candidate; Offer; Onboarding Task | G20: People ops with records | H20: resumes, interview notes, checks, forms | I20: role + stage + authority | J20: decision/approval gate | K20: hire/onboarding record | L20: People dashboard | M20: Ratified | N20: P2 | O20: Not ATS | P20: Extended

Sheet 06_Work_Packs
A1: Work Packs — Bundles of CaseSpace Templates
A2: A work pack packages one standing CaseSpace, repeatable child CaseSpaces, default proof rules, and client-safe dashboards.
A4: Work Pack | B4: Client Door | C4: Standing CaseSpace | D4: Child Templates | E4: Default Client Tabs | F4: Operator Buckets | G4: Likely Integrations | H4: Manual Bridge Removed | I4: Minimum Proof | J4: Seal Rule | K4: Series
A5: Permit & Bridge | B5: Start Permit Path | C5: Project / Applicant / Site | D5: Path Sheet; Lane Review; Missing Fact; Draft Filing; Agency Question | E5: Overview, Intake, Documents, Decisions, Next Steps | F5: Today; Waiting on Client; Waiting on Third Party; Needs Judgment | G5: Drive, Gmail, Calendar, parcel/site docs, agency forms | H5: manual permit-lane guessing, re-keying, email chasing | I5: authority, site facts, lane decision, sent packet, response | J5: all required lanes have decision or deferral + packet sealed | K5: MUNI/P0
A6: Grant Readiness | B6: Check Grant Readiness | C6: Opportunity / Applicant | D6: Eligibility; Authority; Match; Budget; Narrative; Partner; Submission | E6: Overview, Intake, Documents, Decisions, Next Steps | F6: Deadline risk; Missing match; Waiting on partner | G6: Drive, Gmail, NOFO, budget sheets, calendar | H6: NOFO translation and document scramble | I6: eligibility memo, match proof, partner commitments, submission receipt | J6: application submitted or no-go decision sealed | K6: GRANT/P0
A7: STAY Property Memory | B7: Run Property Record | C7: Property | D7: Guest Stay; Turnover; Maintenance; Incident; Receipt; Vendor | E7: Overview, Intake, Documents, Decisions, Next Steps | F7: Today; Waiting on cleaner; Vendor; Stuck/risk | G7: Airbnb, Gmail, Calendar, Drive, photos, receipts | H7: owner as memory and bridge between PMS/cleaner/vendors | I7: booking, cleaner assignment, turnover proof, maintenance closeout | J7: stay/turnover/issue closed with proof and rollup | K7: STAY/P0
A8: Workforce Time & Attendance | B8: Run Timesheet Record | C8: Department / Crew / Project | D8: Shift; Timesheet; Leave; Overtime; Training; Incident | E8: Overview, Intake, Documents, Decisions, Next Steps | F8: Ready for approval; Exceptions; Payroll-ready | G8: Calendar, time entry, supervisor notes, payroll export | H8: supervisor babysitting timesheets and exports | I8: clock proof, supervisor approval, exception notes, payroll export | J8: timesheet approved/exported or exception sealed | K8: PEOPLE/P1
A9: MUNI Records & Board | B9: Build Board/Record Packet | C9: Department / Board | D9: Request; Packet Item; Document; Review; Decision; Response | E9: Overview, Intake, Documents, Decisions, Next Steps | F9: Due soon; Waiting on reviewer; Ready to send | G9: Gmail, Drive, agenda system, public records inbox | H9: packet/record hunting across inboxes and drives | I9: receipt date, responsive docs, review, decision, response sent | J9: packet published or request response sealed | K9: MUNI/P1
A10: BIZ Client Delivery | B10: Run Client Matter | C10: Client / Project | D10: Task; Draft; Decision; Invoice; Handoff | E10: Overview, Intake, Documents, Decisions, Next Steps | F10: Ready to send; Needs Nate Judgment; Waiting client | G10: Gmail, Drive, Calendar, docs, invoices | H10: operator rewriting status from memory | I10: scope, drafts, decisions, sent deliverable, invoice proof | J10: deliverable sent and handoff/next step sealed | K10: BIZ/P1
A11: LIVE Release Control | B11: Run Release Record | C11: App / Repo | D11: Bug; Feature; Release; Incident; Env Change | E11: Overview, Intake, Documents, Decisions, Next Steps | F11: Ready to deploy; Stuck; Recently sealed | G11: GitHub, Vercel, local scripts, logs, screenshots | H11: manual local/live bridge and lost release notes | I11: status check, deploy checklist, release note, screenshot | J11: release/incident closed with proof | K11: LIVE/P1
A12: Property Maintenance | B12: Close Issue | C12: Property / Asset | D12: Issue; Vendor; Inspection; Receipt; Photo; Closeout | E12: Overview, Intake, Documents, Decisions, Next Steps | F12: Safety/risk; Waiting vendor; Ready close | G12: Photos, texts, invoices, calendar, Drive | H12: owner/vendor memory bridge | I12: issue report, vendor assignment, repair proof, receipt | J12: issue closed with before/after proof | K12: PROPERTY/P1
A13: Procurement & Vendor Handoff | B13: Organize Purchase | C13: Project / Department | D13: Quote; Vendor; Approval; Delivery; Acceptance | E13: Overview, Intake, Documents, Decisions, Next Steps | F13: Needs approval; Waiting vendor; Ready accept | G13: Gmail, Drive, quotes, forms, calendar | H13: manual quote comparison and approval handoff | I13: quote record, authority approval, delivery/acceptance | J13: purchase accepted or rejected and sealed | K13: OPS/P2
A14: Policy/SOP Stewardship | B14: Update SOP | C14: Department / Process | D14: Draft; Decision; Training; Acknowledgment; Revision | E14: Overview, Intake, Documents, Decisions, Next Steps | F14: Needs decision; Needs training; Recently ratified | G14: Drive, Gmail, meeting notes, policy docs | H14: policy in docs but not in operating memory | I14: draft, approval, adoption/ratification, training proof | J14: ratified SOP/policy with rollup history | K14: CONTINUITY/P0

Sheet 07_Dashboards
A1: Dashboards — Same Record, Different Surfaces
A2: Dashboards are views over the same CaseSpace state. Client sees calm; operator sees movement; system keeps proof.
A4: KPI | B4: Formula / Value | C4: Meaning | H4: Family | I4: Template Count | J4: P0 | K4: P1 | L4: P2
A5: Series 1 Templates | B5: =COUNTA('05_Series1_Templates'!C5:C20) | C5: Number of Series 1 doors/templates | H5: ALL | I5: =COUNTIF('05_Series1_Templates'!$B$5:$B$20,"ALL") | J5: =COUNTIFS('05_Series1_Templates'!$B$5:$B$20,"ALL",'05_Series1_Templates'!$N$5:$N$20,"P0") | K5: =COUNTIFS('05_Series1_Templates'!$B$5:$B$20,"ALL",'05_Series1_Templates'!$N$5:$N$20,"P1") | L5: =COUNTIFS('05_Series1_Templates'!$B$5:$B$20,"ALL",'05_Series1_Templates'!$N$5:$N$20,"P2")
A6: P0 Templates | B6: =COUNTIF('05_Series1_Templates'!N5:N20,"P0") | C6: Immediate build/sales focus | H6: MUNI | I6: =COUNTIF('05_Series1_Templates'!$B$5:$B$20,"MUNI")+COUNTIF('05_Series1_Templates'!$B$5:$B$20,"MUNI/BIZ") | J6: =COUNTIFS('05_Series1_Templates'!$B$5:$B$20,"MUNI",'05_Series1_Templates'!$N$5:$N$20,"P0")+COUNTIFS('05_Series1_Templates'!$B$5:$B$20,"MUNI/BIZ",'05_Series1_Templates'!$N$5:$N$20,"P0") | K6: =COUNTIFS('05_Series1_Templates'!$B$5:$B$20,"MUNI",'05_Series1_Templates'!$N$5:$N$20,"P1")+COUNTIFS('05_Series1_Templates'!$B$5:$B$20,"MUNI/BIZ",'05_Series1_Templates'!$N$5:$N$20,"P1") | L6: =COUNTIFS('05_Series1_Templates'!$B$5:$B$20,"MUNI",'05_Series1_Templates'!$N$5:$N$20,"P2")+COUNTIFS('05_Series1_Templates'!$B$5:$B$20,"MUNI/BIZ",'05_Series1_Templates'!$N$5:$N$20,"P2")
A7: P1 Templates | B7: =COUNTIF('05_Series1_Templates'!N5:N20,"P1") | C7: Near-term build/sales focus | H7: GRANT | I7: =COUNTIF('05_Series1_Templates'!$B$5:$B$20,"GRANT") | J7: =COUNTIFS('05_Series1_Templates'!$B$5:$B$20,"GRANT",'05_Series1_Templates'!$N$5:$N$20,"P0") | K7: =COUNTIFS('05_Series1_Templates'!$B$5:$B$20,"GRANT",'05_Series1_Templates'!$N$5:$N$20,"P1") | L7: =COUNTIFS('05_Series1_Templates'!$B$5:$B$20,"GRANT",'05_Series1_Templates'!$N$5:$N$20,"P2")
A8: Ratified Templates | B8: =COUNTIF('05_Series1_Templates'!M5:M20,"Ratified") | C8: Templates cleared by doctrine | H8: STAY | I8: =COUNTIF('05_Series1_Templates'!$B$5:$B$20,"STAY") | J8: =COUNTIFS('05_Series1_Templates'!$B$5:$B$20,"STAY",'05_Series1_Templates'!$N$5:$N$20,"P0") | K8: =COUNTIFS('05_Series1_Templates'!$B$5:$B$20,"STAY",'05_Series1_Templates'!$N$5:$N$20,"P1") | L8: =COUNTIFS('05_Series1_Templates'!$B$5:$B$20,"STAY",'05_Series1_Templates'!$N$5:$N$20,"P2")
A9: Work Packs | B9: =COUNTA('06_Work_Packs'!A5:A14) | C9: Bundled CaseSpace packages | H9: PEOPLE | I9: =COUNTIF('05_Series1_Templates'!$B$5:$B$20,"PEOPLE") | J9: =COUNTIFS('05_Series1_Templates'!$B$5:$B$20,"PEOPLE",'05_Series1_Templates'!$N$5:$N$20,"P0") | K9: =COUNTIFS('05_Series1_Templates'!$B$5:$B$20,"PEOPLE",'05_Series1_Templates'!$N$5:$N$20,"P1") | L9: =COUNTIFS('05_Series1_Templates'!$B$5:$B$20,"PEOPLE",'05_Series1_Templates'!$N$5:$N$20,"P2")
A10: Permit Lanes | B10: =COUNTA('08_Permit_Bridge_Lanes'!B5:B17) | C10: Permit & Bridge review lanes | H10: BIZ | I10: =COUNTIF('05_Series1_Templates'!$B$5:$B$20,"BIZ")+COUNTIF('05_Series1_Templates'!$B$5:$B$20,"MUNI/BIZ") | J10: =COUNTIFS('05_Series1_Templates'!$B$5:$B$20,"BIZ",'05_Series1_Templates'!$N$5:$N$20,"P0")+COUNTIFS('05_Series1_Templates'!$B$5:$B$20,"MUNI/BIZ",'05_Series1_Templates'!$N$5:$N$20,"P0") | K10: =COUNTIFS('05_Series1_Templates'!$B$5:$B$20,"BIZ",'05_Series1_Templates'!$N$5:$N$20,"P1")+COUNTIFS('05_Series1_Templates'!$B$5:$B$20,"MUNI/BIZ",'05_Series1_Templates'!$N$5:$N$20,"P1") | L10: =COUNTIFS('05_Series1_Templates'!$B$5:$B$20,"BIZ",'05_Series1_Templates'!$N$5:$N$20,"P2")+COUNTIFS('05_Series1_Templates'!$B$5:$B$20,"MUNI/BIZ",'05_Series1_Templates'!$N$5:$N$20,"P2")
H11: LIVE | I11: =COUNTIF('05_Series1_Templates'!$B$5:$B$20,"LIVE") | J11: =COUNTIFS('05_Series1_Templates'!$B$5:$B$20,"LIVE",'05_Series1_Templates'!$N$5:$N$20,"P0") | K11: =COUNTIFS('05_Series1_Templates'!$B$5:$B$20,"LIVE",'05_Series1_Templates'!$N$5:$N$20,"P1") | L11: =COUNTIFS('05_Series1_Templates'!$B$5:$B$20,"LIVE",'05_Series1_Templates'!$N$5:$N$20,"P2")
H12: PROPERTY | I12: =COUNTIF('05_Series1_Templates'!$B$5:$B$20,"PROPERTY") | J12: =COUNTIFS('05_Series1_Templates'!$B$5:$B$20,"PROPERTY",'05_Series1_Templates'!$N$5:$N$20,"P0") | K12: =COUNTIFS('05_Series1_Templates'!$B$5:$B$20,"PROPERTY",'05_Series1_Templates'!$N$5:$N$20,"P1") | L12: =COUNTIFS('05_Series1_Templates'!$B$5:$B$20,"PROPERTY",'05_Series1_Templates'!$N$5:$N$20,"P2")
A13: Dashboard Layer | B13: Audience | C13: Question Answered | D13: Source Fields | E13: Primary Widgets | F13: Do Not Show | H13: FINANCE | I13: =COUNTIF('05_Series1_Templates'!$B$5:$B$20,"FINANCE") | J13: =COUNTIFS('05_Series1_Templates'!$B$5:$B$20,"FINANCE",'05_Series1_Templates'!$N$5:$N$20,"P0") | K13: =COUNTIFS('05_Series1_Templates'!$B$5:$B$20,"FINANCE",'05_Series1_Templates'!$N$5:$N$20,"P1") | L13: =COUNTIFS('05_Series1_Templates'!$B$5:$B$20,"FINANCE",'05_Series1_Templates'!$N$5:$N$20,"P2")
A14: Client CaseSpace | B14: Client | C14: What are we doing, what do we know, what is missing, what happens next? | D14: Overview, Intake, Documents, Decisions, Next Steps | E14: five tabs; Path Sheet; Next Steps; Record | F14: runtime names, CAL/PRM, internal audit mechanics | H14: OPS | I14: =COUNTIF('05_Series1_Templates'!$B$5:$B$20,"OPS") | J14: =COUNTIFS('05_Series1_Templates'!$B$5:$B$20,"OPS",'05_Series1_Templates'!$N$5:$N$20,"P0") | K14: =COUNTIFS('05_Series1_Templates'!$B$5:$B$20,"OPS",'05_Series1_Templates'!$N$5:$N$20,"P1") | L14: =COUNTIFS('05_Series1_Templates'!$B$5:$B$20,"OPS",'05_Series1_Templates'!$N$5:$N$20,"P2")
A15: Operator Movement Board | B15: Nate/PublicLogic | C15: What needs movement today? | D15: status, owner, waiting_on, next_action, risk | E15: Today; Waiting Client; Waiting Third Party; Needs Judgment; Ready to Send; Stuck/Risk; Recently Sealed | F15: full architecture or backend logs
A16: Stewardship Dashboard | B16: PublicLogic admin | C16: Which work packs/templates are active, repeated, and worth productizing? | D16: family, template, occurrences, status, priority | E16: work pack counts; 1x/2x/3x pattern tracker; backlog | F16: client private details
A17: Proof Dashboard | B17: System/Internal | C17: What was captured, advanced, decided, and sealed? | D17: recordstream, proof events, seal records, rollups | E17: open proof gaps; sealed records; missing proof | F17: subjective status without evidence
A18: Bridge Dashboard | B18: Sales/Product | C18: Where are humans still bridging systems? | D18: systems count, manual re-entry, people count, risk, missing docs | E18: bridge score; bridge removed; integration map | F18: claims that the system automated what is still manual

Sheet 08_Permit_Bridge_Lanes
A1: Permit & Bridge Lanes — Readiness Before Software
A2: Permit & Bridge is a readiness lane system: it asks what probably has to be true before a matter can move.
A4: Lane ID | B4: Lane | C4: Plain-English Question | D4: Sources | E4: Required Facts | F4: Common Docs | G4: Gate / Decision | H4: Bridge Removed | I4: Output | J4: Proof Event | K4: Seal Condition | L4: Client Tab
A5: PB-01 | B5: Front Door / Path Sheet | C5: What are they trying to do? | D5: client intake, email, call notes | E5: desired outcome, property/project, deadline | F5: photos, sketches, existing permits, narrative | G5: scope boundary + no legal/agency decision | H5: freeform emails and ad hoc advice | I5: first Path Sheet + bridge rating | J5: Path Sheet generated | K5: recommended next step visible | L5: Overview
A6: PB-02 | B6: Authority / Applicant | C6: Who can ask, sign, own, or authorize? | D6: client docs, corporate records, owner notes | E6: applicant, owner, agent, authority | F6: deed, authorization, entity docs, vote/authorization | G6: authority check before sending | H6: missing signer/authority chase | I6: authority facts in CaseSpace | J6: authority proof captured | K6: authority accepted or flagged | L6: Intake
A7: PB-03 | B7: Parcel / Site Facts | C7: Where is it and what facts define the site? | D7: maps, assessor, GIS, plans | E7: address, parcel, zoning district, constraints | F7: site plan, assessor card, locus map | G7: site fact completeness gate | H7: re-keying parcel facts into every form | I7: site facts block | J7: site facts proof captured | K7: site facts ready or flagged | L7: Documents
A8: PB-04 | B8: Use / Zoning Lane | C8: What use is proposed and what local lane likely applies? | D8: zoning bylaw, use description, planner notes | E8: existing use, proposed use, district, triggers | F8: narrative, floor/site plan, zoning excerpts | G8: zoning lane/no-go question | H8: guessing which board/process applies | I8: zoning lane note | J8: lane decision recorded | K8: lane selected/deferred | L8: Decisions
A9: PB-05 | B9: Health / Environmental | C9: Does the work touch health, waste, septic, food, air, water, or hazardous issues? | D9: BOH, DEP/EGLE, project docs | E9: health/environment triggers | F9: septic, soil, waste, environmental docs | G9: environmental trigger gate | H9: late discovery of health/environment lane | I9: health/env checklist | J9: trigger decision proof | K9: trigger closed or escalated | L9: Decisions
A10: PB-06 | B10: Building / Fire / Life Safety | C10: Does the work need building/fire review or inspection? | D10: building/fire forms, plans, code notes | E10: construction type, occupancy, safety triggers | F10: plans, specs, contractor info | G10: safety/code lane gate | H10: operator manually bridging inspector questions | I10: building/fire lane note | J10: review/inspection proof | K10: ready for filing or flagged | L10: Decisions
A11: PB-07 | B11: Conservation / Stormwater / Wetlands | C11: Does land/water protection review apply? | D11: maps, site photos, conservation notes | E11: wetlands, buffer, stormwater, drainage | F11: site plan, photos, wetlands map | G11: conservation/stormwater gate | H11: late conservation surprise | I11: conservation lane note | J11: trigger proof captured | K11: lane closed or escalated | L11: Decisions
A12: PB-08 | B12: DPW / Utilities / Access | C12: Does the project affect road, driveway, water, sewer, drainage, or access? | D12: DPW forms, utility notes, site plan | E12: access, trench, utility, driveway facts | F12: driveway permit, utility plan, trench docs | G12: DPW/utility gate | H12: cross-department chasing | I12: DPW/utility lane record | J12: review proof | K12: lane ready or waiting | L12: Documents
A13: PB-09 | B13: Board / Notice / Hearing | C13: Does a board, public notice, abutter notice, or hearing control timing? | D13: town calendar, bylaws, notices | E13: board, deadline, hearing dates, notice rules | F13: notice draft, abutter list, agenda request | G13: calendar/notice gate | H13: missed meeting cycle | I13: hearing/notice timeline | J13: notice/hearing proof | K13: scheduled or no board needed | L13: Next Steps
A14: PB-10 | B14: Fees / Procurement / Vendor | C14: What money, quotes, vendors, or approvals must be in place? | D14: quotes, fee schedule, invoices | E14: fees, quote count, vendor responsibility | F14: quotes, W-9, fee calc, PO docs | G14: approval/procurement gate | H14: manual quote/approval bridge | I14: vendor/fee record | J14: approval proof | K14: approved or blocked | L14: Documents
A15: PB-11 | B15: Funding / Grant / Match | C15: Is money or grant readiness part of the bridge? | D15: NOFO, budget, match docs | E15: eligibility, match, partner, deadline | F15: budget, match letter, partner letters | G15: grant readiness gate | H15: grant scramble after permit lane starts | I15: funding lane note | J15: grant/match proof | K15: grant path/no-go sealed | L15: Decisions
... A17: PB-13 | B17: Inspection / Closeout | C17: How does this finish and what proof survives? | D17: inspection notes, photos, approvals | E17: inspection result, conditions, closeout docs | F17: inspection report, photos, final approval | G17: seal gate | H17: no one knows what happened after approval | I17: sealed record + rollup | J17: closeout proof | K17: ARCHIEVE sealed child rollup | L17: Record

Sheet 09_Doors_Same_System
A1: All Doors, Same System
A2: Time & attendance, permits, grants, STAY, LIVE, and client work are doors into the same four-action loop: Capture, Classify, Advance, Seal.
A4: Door | B4: Friendly Entry | C4: Capture Input | D4: CaseSpace Skin | E4: Common Child Cases | F4: Advance Gate | G4: Seal Output | H4: Client Sees | I4: System Keeps | J4: Not Separate Product
A5: Path Sheet Entry | B5: Start with messy facts | C5: intake answers, files, links | D5: ALL / triage | E5: Missing Fact; Needed Document; Question | F5: Bridge score + recommended next step | G5: Path Sheet + CaseSpace seed | H5: plain path and next step | I5: record fields + initial proof | J5: Yes
A6: Permit & Bridge | B6: Start a permit/readiness review | C6: property/project facts, docs, deadlines | D6: MUNI | E6: Lane Review; Agency Question; Draft Filing | F6: lane gate + authority/site checks | G6: readiness packet + send proof | H6: likely lanes, missing docs, next step | I6: lane decisions + proof events | J6: Yes
A7: Grant Readiness | B7: Check a grant opportunity | C7: NOFO, budget, partners | D7: GRANT | E7: Eligibility; Match; Narrative; Submission | F7: eligibility + authority + match gate | G7: application/no-go proof | H7: eligibility, missing facts, deadline | I7: submission/readiness proof | J7: Yes
A8: STAY Property Memory | B8: Run the property record | C8: booking, cleaner, vendor, receipt | D8: STAY | E8: Guest Stay; Turnover; Maintenance; Incident | F8: occupancy/cleaning/maintenance precondition | G8: closed stay/issue + proof | H8: documents, decisions, next steps | I8: property memory rollup | J8: Yes
A9: Time & Attendance | B9: Approve a shift/timesheet | C9: clock events, schedule, supervisor notes | D9: PEOPLE | E9: Shift; Leave; Overtime; Timesheet | F9: supervisor approval + payroll export gate | G9: approved/exported timesheet proof | H9: what needs approval or correction | I9: audit record + exception notes | J9: Yes
A10: Client Deliverable | B10: Move a client project | C10: email, docs, meeting notes | D10: BIZ | E10: Task; Draft; Decision; Invoice; Handoff | F10: ready-to-send gate | G10: sent deliverable + record | H10: status, needed input, next step | I10: decision/delivery proof | J10: Yes
A11: Release / Deployment | B11: Move local/live code safely | C11: GitHub, local scripts, Vercel, logs | D11: LIVE | E11: Bug; Feature; Release; Incident | F11: surface-not-state + deploy checklist | G11: release/incident proof | H11: current status and what changed | I11: release notes + deploy proof | J11: Yes
A12: Maintenance / Incident | B12: Close a real-world issue | C12: photo, text, vendor quote, inspection | D12: PROPERTY | E12: Issue; Vendor; Inspection; Receipt | F12: risk/safety + repair gate | G12: closed issue + before/after proof | H12: risk, vendor status, next action | I12: repair proof + receipt | J12: Yes
A13: Public Records / Board Packet | B13: Assemble a record or packet | C13: request, agenda item, attachments | D13: MUNI | E13: Request; Document; Review; Packet Item | F13: deadline + review gate | G13: published/sent proof | H13: documents, decisions, next steps | I13: response/packet proof | J13: Yes
A14: Policy / SOP | B14: Steward continuity | C14: drafts, notes, decisions, approvals | D14: CONTINUITY | E14: Draft; Decision; Training; Acknowledgment | F14: approval/ratification gate | G14: ratified SOP/policy record | H14: what changed and who decided | I14: decision + training proof | J14: Yes

Sheet 10_Time_Attendance
A1: Time & Attendance Work Pack — A Template, Not an HRIS
A2: One template among many. Users compose their own experience from templates, tools, and information; time & attendance is a single work pack door, not the output. It is not an HRIS.
A4: Item | B4: Definition | C4: Canonical Rule / Build Note | D4: Fence
A5: Doctrine | B5: PublicLogic does not sell timekeeping software. | C5: Time & Attendance is a work pack door into CaseSpace. It organizes and proves time-related work without replacing HRIS/payroll. | D5: Doctrine
A6: Standing CaseSpace | B6: Department / Crew / Project / Property | C6: Ongoing unit containing shift, leave, overtime, training, incident, and timesheet children. | D6: Doctrine
A7: Closing Child: Shift | B7: Finite work window | C7: Captures date, person, role, location/project, clock in/out, exception note, supervisor. | D7: Template
A8: Closing Child: Timesheet | B8: Payroll-period record | C8: Rolls up shifts, leave, overtime, missing approvals, and payroll export proof. | D8: Template
A9: Closing Child: Leave | B9: Leave request/approval | C9: Captures request, balance/source system reference, supervisor decision, coverage impact. | D9: Template
A10: Closing Child: Overtime | B10: Exception/approval | C10: Captures reason, authorization, hours, project/cost center, approval proof. | D10: Template
A11: Closing Child: Training | B11: Completion/proof | C11: Captures required training, due date, completion record, certificate/photo/document. | D11: Template
A12: Closing Child: Incident | B12: Time-related incident | C12: Captures late/no-show/injury/exception, supervisor note, decision, closeout proof. | D12: Template
A13: Capture Sources | B13: Clock/time entries, schedule, calendar, supervisor notes, employee messages, payroll export, photos/docs | C13: Sources are not the record. They are captured into CaseSpace. | D13: Doctrine
A14: Classify Fields | B14: person, role, department, project/property, date, shift window, exception type, approval status | C14: Makes records searchable/rollup-ready without exposing AI/search plumbing. | D14: Build Spec
A15: Advance Gates | B15: Supervisor approval; exception review; payroll export readiness; compliance/risk review | C15: No payroll handoff until approval and exceptions are accounted for. | D15: Doctrine
... A17: Dashboard Buckets | B17: Ready for Approval; Exceptions; Missing Proof; Payroll Ready; Waiting on Employee; Waiting on Supervisor; Recently Sealed | C17: Views over CaseSpace state, not separate systems. | D17: Build Spec
A20: Bridge Component | B20: Score 0 | C20: Score 1 | D20: Score 2 | E20: Score 3 | F20: Notes
A21: Systems involved | B21: 1 system | C21: 2 systems | D21: 3 systems | E21: 4+ systems | F21: Clock/calendar/payroll/spreadsheet/email count as separate systems
A22: Manual re-entry | B22: none | C22: one re-entry | D22: two re-entries | E22: three+ re-entries | F22: Human-bridge burden
A23: People/approvers | B23: 1 person | C23: 2 people | D23: 3 people | E23: 4+ people | F23: Employee, supervisor, payroll, HR/admin
A24: Compliance/deadline risk | B24: none | C24: internal deadline | D24: payroll deadline | E24: law/contract/compliance risk | F24: Municipal/labor contexts increase risk
A25: Missing proof burden | B25: none | C25: minor proof missing | D25: multiple proofs missing | E25: core proof missing | F25: Approvals/certificates/export receipts

Sheet 11_Path_Generator
A1: Path Sheet Generator MVP
A2: First clickable proof: Intake answers → Path Sheet → Bridge Rating → CaseSpace seed → Next Steps.
A4: Field | B4: Type | C4: Prompt / Meaning | D4: Required? | E4: Output Surface
A5: Desired Outcome | B5: text | C5: What are we trying to get done? | D5: Required | E5: Path Sheet
A6: Matter Type | B6: list | C6: STAY/MUNI/BIZ/GRANT/LIVE/HOME/PEOPLE/OPS/PROPERTY | D6: Required | E6: CaseSpace seed
A7: Current Reality | B7: text | C7: What is true today? | D7: Required | E7: Path Sheet
A8: Known Facts | B8: array | C8: Facts already available | D8: Required | E8: CaseSpace seed
A9: Missing Facts | B9: array | C9: Facts needed before movement | D9: Required | E9: Path Sheet
A10: Documents Available | B10: array | C10: Documents already supplied | D10: Recommended | E10: Documents tab
A11: Documents Needed | B11: array | C11: Needed documents | D11: Required | E11: Path Sheet
A12: People / Parties | B12: array | C12: Owners, approvers, vendors, agencies, clients | D12: Required | E12: Bridge Score
A13: Systems Involved | B13: number/list | C13: Drive, Gmail, calendar, portal, PMS, payroll, etc. | D13: Required | E13: Bridge Score
A14: Manual Re-entry Points | B14: number/list | C14: Places humans copy/export/re-key | D14: Required | E14: Bridge Score
A15: Deadline / Regulatory Risk | B15: 0-3 score | C15: None/internal/deadline/legal-regulatory | D15: Required | E15: Bridge Score
... A17: Recommended Next Step | B17: text | C17: What happens next? | D17: Required | E17: Next Steps
A20: Component | B20: Output | C20: Fields | D20: Notes
A21: Bridge Score | B21: =systems + manual re-entry + people/approvers + risk + missing proof | C21: Low 0-4; Medium 5-8; High 9-12; Critical 13+ | D21: Formula is intentionally explainable.
A22: MVP Output 1 | B22: Printable Path Sheet | C22: Desired Outcome; Likely Lanes; Missing Facts; Needed Documents; Red Flags; Questions; Bridge Rating; Next Step | D22: Client-safe.
A23: MVP Output 2 | B23: CaseSpace seed JSON | C23: case_type, family, desired_outcome, known_facts, missing_facts, documents_needed, bridge_score, next_steps | D23: Internal seed.
A24: MVP Output 3 | B24: First Next Steps block | C24: Current Status; What changed; Need from client; PublicLogic next; Risks/decisions; Next checkpoint | D24: Start weekly rhythm.

Sheet 12_Client_CaseSpace_View
A1: Client CaseSpace View — Five Tabs Maximum
A2: Every client-facing CaseSpace uses the same calm surface. Everything else is internal.
A4: Tab | B4: Shows | C4: Question Answered | D4: Visibility
A5: Overview | B5: Desired outcome; current status; bridge rating; next checkpoint | C5: What are we trying to get done? | D5: Client
A6: Intake | B6: Known facts; missing facts; people; deadlines; open questions | C6: What do we know and what is missing? | D6: Client
A7: Documents | B7: Available docs; needed docs; record home; proof gaps | C7: Where are the documents? | D7: Client
A8: Decisions | B8: Decision log; who decided; date; authority/reference | C8: What was decided? | D8: Client
A9: Next Steps | B9: What we need from you; what PublicLogic is doing; risks; next checkpoint | C9: What happens next? | D9: Client

Sheet 13_Operator_Page
A1: Operator Page — Movement, Not Dashboards
A2: One daily page for Nate/PublicLogic. It answers: what needs movement today?
A4: Bucket | B4: Definition | C4: Source Field | D4: Action
A5: Today | B5: Work with an action due now or due today | C5: CaseSpace status + due date | D5: Move or defer
A6: Waiting On Client | B6: Needs client input/document/decision | C6: waiting_on = client | D6: Send request or hold
A7: Waiting On Third Party | B7: Agency/vendor/partner/other party is the blocker | C7: waiting_on = third_party | D7: Follow up or update risk
A8: Needs Nate Judgment | B8: Cannot advance without Nate/PublicLogic decision | C8: judgment_required = yes | D8: Decide or schedule review
A9: Ready to Send | B9: Draft/packet/update is ready for final review/send | C9: ready_to_send = yes | D9: Send or revise
A10: Stuck / Risk | B10: Deadline, missing proof, conflict, or unclear ownership | C10: risk_flag = yes | D10: Escalate and document
A11: Recently Sealed | B11: Closed cases this week | C11: seal_status = sealed | D11: Show progress and proof
A14: Weekly Update Field | B14: Meaning
A15: Current Status | B15: One sentence
A16: What changed | B16: Since last checkpoint
A17: What we need from you | B17: Specific client asks
A18: What PublicLogic is doing next | B18: Operator commitments
A19: Risks / decisions | B19: Risks, blockers, decisions needed
A20: Next checkpoint | B20: Date/time or trigger

Sheet 14_Feature_Gate
A1: Feature Gate — Rule of Three
A2: No new client-specific feature until the same need appears three times. Before that: template, note, checklist, or manual step.
A4: Stage | B4: Threshold | C4: Allowed Action | D4: Evidence
A5: Observation | B5: 1x | C5: Log in backlog. Do not build. | D5: Client ask / operator pain
A6: Pattern Candidate | B6: 2x | C6: Create checklist/template note. Do not build runtime feature. | D6: Similar ask appears again
A7: Template | B7: 3x | C7: Promote to template/work pack if it fits CaseSpace loop. | D7: Same need appears third time
A8: Product Surface | B8: After template proves usage | C8: Build UI/launcher/dashboard only after pattern is stable. | D8: Template has repeat use and proof
A11: ID | B11: Need | C11: Family | D11: Seen Count | E11: Current Treatment | F11: Status
A12: O-001 | B12: Permit lane confusion | C12: Permit & Bridge | D12: 1 | E12: Template note | F12: Open
A13: O-002 | B13: Weekly update rewrite burden | C13: All | D13: 2 | E13: Checklist/view spec | F13: Open
A14: O-003 | B14: Timesheet approval bridge | C14: PEOPLE | D14: 1 | E14: Work pack seed | F14: Open

Sheet 15_Competitive_Positioning
A1: Competitive Positioning — Primitive + Doctrine, Not Vocabulary
A2: Final mid-2026 pressure-test: do not win on 'proof/audit trail/institutional memory' words. Win on standing/closing CaseSpaces, seal-upward architecture, non-replacement discipline, and stewardship.
A4: Section | B4: Position | C4: Why it matters | D4: Action | E4: Source / Guardrail
A5: Category We Own | B5: Governed work library + CaseSpace runtime | C5: Ready-to-run templates for rule-bound operational work, backed by stewardship. | D5: Use | E5: Do not call it AI OS, front door, CRM, legal automation, PMS, or grant management software.
A6: Plain English | B6: Complicated work → standing/closing CaseSpace → next steps → seal upward | C6: This shows structure, not just logging. | D6: Use | E6: Define CaseSpace every time.
A7: Hero Claim | B7: Closing work seals upward into standing work across systems | C7: Harder to copy than 'audit trail' language. | D7: Lead | E7: Primitive + doctrine + stewardship.
A8: Non-Replacement Claim | B8: We do not want to be your system of record | C8: Separates PJ from Polimorphic/GovWell/Tyler/OpenGov/Granicus. | D8: Lead | E8: External systems remain signal/surface sources.
A9: Stewardship Claim | B9: Human-supported library upkeep | C9: Software-only incumbents can copy logs; they resist local messy stewardship. | D9: Lead | E9: Name and price this tier.
A10: Avoid List | B10: AI operating system; front door; inbound services; municipal CRM; case management from intake to resolution; legal advice engine; PMS; grant management software | C10: These drag PublicLogic into someone else's category. | D10: Avoid | E10: Use only to explain what PJ is not.
A12: Competitor Type | B12: They sell | C12: PublicLogic sells | D12: Threat / Guardrail | E12: Rating
A13: Polimorphic | B13: AI front desk, resident service delivery, CRM, case management, institutional knowledge/audit-trail narrative | C13: Governed work templates, CaseSpace nesting, seal-upward proof, readiness, stewardship | D13: High narrative threat; partner-or-competitor. Do not pitch inbound/resident front door. | E13: High
A14: GovWell | B14: AI operating system for modern government, permitting/licensing/community development system of record | C14: Permit & Bridge readiness before/beside/after formal systems; broader governed work library | D14: High municipal budget threat. Do not pitch as permitting OS. | E14: High
A15: Granicus / OpenGov / Tyler | B15: Government systems of record, digital services, AI agents, records, ERP/permitting/courts/budget platforms | C15: Pre-system and cross-system work organization, evidence, handoff, portable continuity | D15: Low now, Medium-rising. Watch cross-system records rollup / institutional-memory features. | E15: Low→Medium
A16: Tonkean / Coupa | B16: Enterprise procurement/legal/IT intake and process orchestration | C16: Smaller, civic/project/property/grant CaseSpaces plus stewardship | D16: High conceptual cousin, low buyer collision after Coupa acquisition. | E16: Strategic watch
... A19: Guesty / Hostaway / Hospitable / OwnerRez | B19: STR PMS/channel management/guest messaging/revenue ops | C19: STAY property memory, exception handling, maintenance proof, vendor continuity, owner record | D19: Low direct threat; STAY is white space but smaller revenue lane. | E19: Low

Sheet 16_Build_Order
A1: Build Order — Prove the Moat, Not the Universe
A2: The first clickable loop must prove: Path Sheet Entry → CaseSpace seed → standing/closing child → next steps → seal upward into parent → stewardship note.
A4: ID | B4: Build Item | C4: Why | D4: Depends On | E4: Score | F4: Priority | G4: Status | H4: First Demo | I4: Notes
A5: B-001 | B5: Path Sheet Entry Generator | C5: First clickable proof of PJ Lite and all doors | D5: 11_Path_Generator | E5: 100 | F5: P0 | G5: Next | H5: Path Sheet + bridge rating + seed JSON | I5: Replaces manual triage; do not call it front door
A6: B-002 | B6: Series 1 Door Seeder | C6: Creates CaseSpace seed JSON from selected template | D6: 05_Series1_Templates | E6: 96 | F6: P0 | G6: Next | H6: Door → CaseSpace JSON | I6: All doors same system
A7: B-003 | B7: Standing/Closing CaseSpace Demo | C7: Shows closing work inside standing parent | D7: 04_CaseSpace_Schema | E7: 95 | F7: P0 | G7: Next | H7: Property/Project parent with one closing child | I7: This is the moat demo
A8: B-004 | B8: Seal-Upward Closeout | C8: Proves child closeout and parent rollup reference | D8: 04_CaseSpace_Schema | E8: 94 | F8: P0 | G8: Next | H8: Close child → sealed proof package → parent reference | I8: Not just audit log
A9: B-005 | B9: Operator Movement Board | C9: Stops Nate being the router | D9: 13_Operator_Page + 07_Dashboards | E9: 90 | F9: P0 | G9: Next | H9: Today/Waiting/Judgment board | I9: Internal first
A10: B-006 | B10: Weekly Next Steps View | C10: Client calm and repeated update format | D10: 12_Client_CaseSpace_View | E10: 88 | F10: P1 | G10: Next | H10: six-field update | I10: Replaces manual client status prose
A11: B-007 | B11: Permit & Bridge Lane Picker | C11: Best municipal/client bridge wedge | D11: 08_Permit_Bridge_Lanes | E11: 86 | F11: P1 | G11: Next | H11: Applicant/site Path Sheet | I11: Do not call it permitting software
A12: B-008 | B12: Grant Readiness CaseSpace | C12: Strong cross-domain revenue/proof lane | D12: 05_Series1_Templates | E12: 84 | F12: P1 | G12: Next | H12: Opportunity parent + submission child | I12: Grant readiness before grant management
A13: B-009 | B13: STAY Property Memory CaseSpace | C13: Dogfooding through Kendall Pond | D13: 05_Series1_Templates | E13: 82 | F13: P1 | G13: Next | H13: Property parent + maintenance/turnover child | I13: Guesty runs bookings; PJ remembers property
A14: B-010 | B14: Stewardship Tier Pack | C14: Makes human stewardship visible and priced | D14: 21_Partner_Protocol | E14: 80 | F14: P1 | G14: Next | H14: Stewardship scope + update cadence | I14: Moat against software-only competitors
A15: B-011 | B15: Work Pack Installer | C15: Installs parent + child templates + dashboard + proof rules | D15: 06_Work_Packs | E15: 78 | F15: P2 | G15: Later | H15: one installed work pack | I15: Template-driven

Sheet 17_Backlog
A1: Backlog — Pattern and Build Queue
A2: Backlog items are pattern-managed. Custom asks do not become features until the need repeats three times.
A4: ID | B4: Item | C4: Description | D4: Type | E4: Priority | F4: Status | G4: Source Sheet
A5: B-020 | B5: Series 1 Door Seeder | C5: Build selector that turns Series 1 template into CaseSpace seed JSON | D5: Product | E5: P0 | F5: Open | G5: 05_Series1_Templates
A6: B-021 | B6: Permit & Bridge Lane Picker | C6: Interactive lane questionnaire and bridge rating for Permit & Bridge | D6: Product | E6: P0 | F6: Open | G6: 08_Permit_Bridge_Lanes
A7: B-022 | B7: Dashboard State Model | C7: Define shared fields powering client/operator/system dashboards | D7: Product | E7: P0 | F7: Open | G7: 07_Dashboards
A8: B-023 | B8: Time & Attendance Work Pack Seed | C8: Seed JSON and proof checklist for workforce template | D8: Product | E8: P1 | F8: Open | G8: 10_Time_Attendance
A9: B-024 | B9: Work Pack Installer | C9: Install a full work pack: parent CaseSpace, child templates, dashboards, proof rules | D9: Product | E9: P0 | F9: Open | G9: 06_Work_Packs
A10: B-025 | B10: Weekly Update Generator | C10: Generate six-field client update from CaseSpace state | D10: Product | E10: P1 | F10: Open | G10: 13_Operator_Page
A11: B-026 | B11: Seal Checklist | C11: Close child CaseSpace with required proof and rollup reference | D11: Product | E11: P1 | F11: Open | G11: 04_CaseSpace_Schema

Sheet 18_Template_Ratifier
A1: Template Ratifier — Add Doors Without Forking the System
A2: Every new template/work pack must pass these checks before becoming Series 1/2/3.
A4: ID | B4: Check | C4: Level | D4: Evidence Required | E4: Status
A5: R-001 | B5: Maps to standing/closing CaseSpace | C5: Required | D5: Template declares parent and closing children | E5: PASS
A6: R-002 | B6: Uses Capture/Classify/Advance/Seal | C6: Required | D6: Template names the four actions and proof output | E6: PASS
A7: R-003 | B7: Names manual bridge removed | C7: Required | D7: P-002 proof of fix is explicit | E7: PASS
A8: R-004 | B8: Defines searchable fields | C8: Required | D8: P-001 proof of fix is explicit | E8: PASS
A9: R-005 | B9: Client surface stays PJ Lite | C9: Required | D9: Path Sheet / CaseSpace / Next Steps / Record only | E9: PASS
A10: R-006 | B10: Not a systems replacement claim | C10: Required | D10: Fenced as work pack/template, not HRIS/PMS/permitting/etc. | E10: PASS
A11: R-007 | B11: Seal rule included | C11: Required | D11: Closing children have proof and closeout conditions | E11: PASS
A12: R-008 | B12: Dashboard is a view, not record | C12: Required | D12: Dashboard reads CaseSpace state | E12: PASS
A13: R-009 | B13: Counsel-ready / no determinations | C13: Required | D13: Template uses law-aware language without legal advice or agency determinations | E13: PASS
A14: R-010 | B14: Partner-safe positioning | C14: Required | D14: Template does not step into CRM/front-door/permitting/PMS/HRIS/legal replacement language | E14: PASS
A15: R-011 | B15: Standing parent declared | C15: Required | D15: Every closing child identifies the standing parent it can seal into | E15: PASS

Sheet 19_Final_Audit
A1: Final Audit — Series 1 Workbook Release
A2: Confirms the workbook now reflects the competitive teardown: primitive-first positioning, non-replacement, partner-safety, counsel-ready boundaries, and live proof loops.
A4: Check ID | B4: Control | C4: Evidence | D4: Status | E4: Sheets
A5: A-001 | B5: CaseSpace remains the single primitive | C5: All doors map to standing/closing CaseSpaces, not new products. | D5: PASS | E5: 01,04,05,09
A6: A-002 | B6: Hero claim moved from audit/proof words to primitive | C6: Core doctrine and competitive sheet lead with standing/closing + seal-upward. | D6: PASS | E6: 01,15,16
A7: A-003 | B7: Surface-not-state is explicit | C7: External tools are signal/surface sources, not PJ state. | D7: PASS | E7: 01,15,21
A8: A-004 | B8: Non-replacement discipline is explicit | C8: Partner protocol and battlecards say PJ does not become system of record. | D8: PASS | E8: 01,20,21
A9: A-005 | B9: Counsel-ready / no legal advice fence added | C9: Templates organize facts/rules/questions/proof but do not make legal determinations. | D9: PASS | E9: 01,21,22
A10: A-006 | B10: Polimorphic/GovWell threat updated | C10: Battlecards distinguish resident-service/permitting systems from governed work layer. | D10: PASS | E10: 15,20,23
A11: A-007 | B11: Incumbents moved to Low-now / Medium-rising | C11: Watchlist names triggers for Granicus/OpenGov/Tyler encroachment. | D11: PASS | E11: 15,23
A12: A-008 | B12: Tonkean downgraded operationally but watched strategically | C12: Coupa acquisition of Tonkean noted on the competitive sheet and sourced (SRC-006); conceptual cousin, low buyer collision. Not battlecarded. | D12: PASS | E12: 15,24
A13: A-009 | B13: Series 1 launch set defined and tracked | C13: Five launch doors at P0 (Path Sheet Entry, Permit & Bridge, Grant Readiness, Property Memory/STAY, Policy/SOP Stewardship); three PJ Lite Service templates also P0 (Quick Review, Bridge Package, Live CaseSpace); extended templates P1-P2. Eight P0 total, separated by the Track column on sheet 05. | D13: PASS | E13: 05,16,22
A14: A-010 | B14: Policy/SOP Stewardship moved up | C14: P0 and named as core stewardship moat. | D14: PASS | E14: 05,16
A15: A-011 | B15: Front-door/inbound language reduced | C15: Workbook uses Path Sheet Entry / CaseSpace Entry and warns against front-door claims. | D15: PASS | E15: 05,15,20,21
... A22: A-018 | B22: Split-Row combo + industry map closed | C22: Tools mapped as consonant row (invariant), templates/industry as vowel row (overlay); tool x template combos and per-industry combos enumerated; free boundary set to first-pass Path Sheet only. | D22: PASS | E22: 25,26

Sheet 20_Battlecards
A1: Battlecards — How to Answer the Sophisticated Buyer
A2: Use these to keep PJ out of other people's categories while showing why the CaseSpace primitive matters.
A4: Competitor / Objection | B4: What They Already Have | C4: Buyer Confusion | D4: PublicLogic Answer | E4: Proof / Demo Required | F4: Avoid Saying
A5: Polimorphic | B5: AI front desk; resident-service platform; CRM; case management; institutional knowledge/audit-trail narrative | C5: 'Don't they already give me the record and institutional memory?' | D5: Polimorphic may be the CRM/service record. PJ is the governed work layer that nests the work into the property, department, grant, project, policy, or operating record it belongs to, then seals closing work upward across systems. | E5: Show service request/permit/grant/email signals becoming one closing CaseSpace that seals into a standing parent. | F5: Inbound services; AI front desk; resident intake; municipal CRM; from intake to resolution
A6: GovWell | B6: Permitting/licensing/community-development system of record; AI OS for modern government | C6: 'If I buy GovWell, why do I need Permit & Bridge?' | D6: GovWell runs formal permitting/licensing. Permit & Bridge organizes readiness before/beside/after formal systems: facts, missing docs, authority questions, risks, next steps, and proof. | E6: Show Permit & Bridge Path Sheet that does not approve/deny/file anything, then becomes a readiness CaseSpace. | F6: AI permitting OS; permitting software; code-compliance engine
A7: Tyler / OpenGov / Granicus | B7: Large government systems of record, digital services, records, AI agents, ERP/permitting/budget/courts platforms | C7: 'Won't our existing platform already have this?' | D7: Those platforms own domain records. PJ makes the cross-system work portable and provable without replacing them: email, docs, vendor notes, board decisions, grants, and child cases roll into a standing record. | E7: Show a standing project parent with child cases touching multiple systems. | F7: Replacement platform; source of truth for all agency operations
A8: Airtable / Kissflow / Knack | B8: Generic no-code workflow builders with AI/governance/audit features | C8: 'Could a consultant build this in Airtable?' | D8: They can build a base for one client. They do not ship the doctrine, standing/closing primitive, seal-upward rule, law-aware templates, or stewardship upkeep across customers. | E8: Show ratifier + maintained template library + seal checklist. | F8: No-code platform; workflow automation tool
A9: BRYTER / Checkbox | B9: Legal/compliance front doors, matter management, intake/workflow automation, auditable records | C9: 'Is this legal automation?' | D9: No. PublicLogic is counsel-ready, not counsel-replacing. It organizes facts, documents, deadlines, authority questions, and proof so the right decision-maker can act from a cleaner record. | E9: Show no-determination language in each template and counsel-ready export. | F9: Legal advice; legal determinations; matter management
A10: Guesty / Hostaway / Hospitable / OwnerRez | B10: Bookings, channel management, guest messaging, PMS operations | C10: 'Is this another PMS?' | D10: No. Guesty runs bookings. PJ remembers the property: turnover proof, maintenance issues, vendor history, guest exceptions, incident records, and owner continuity. | E10: Show Kendall Pond property parent + maintenance/turnover child cases. | F10: Booking engine; channel manager; PMS
