Workbook
Name LaneList: Control!$B$14:$B$17
Name NatureList: Control!$C$14:$C$15
Name LifecycleList: Control!$D$14:$D$17
Name FamilyList: Control!$E$14:$E$23
Name EventTypeList: Control!$F$14:$F$28
Name StatusList: Control!$G$14:$G$21
Name SignificanceList: Control!$H$14:$H$17
Name SourceList: Control!$I$14:$I$20
Name ConsumerList: Control!$J$14:$J$19
Name RiskList: Control!$K$14:$K$16
Name ResolvedList: Control!$L$14:$L$15
Name TaskStatusList: Control!$M$14:$M$17
Name EvidenceStatusList: Control!$N$14:$N$16
Name YesNoList: Control!$O$14:$O$15
Name CaseList: Control!$P$14:$P$14
Name ConnectorTypeList: Control!$Q$14:$Q$18
Name SignalKindList: Control!$R$14:$R$21
Name DecisionList: Control!$S$14:$S$17
Name ResolutionList: Control!$T$14:$T$16
Name ClaimStatusList: Control!$U$14:$U$17
Name PRRKindList: Control!$V$14:$V$21
Name ReceiptVerbList: Control!$W$14:$W$17
Name HumanVerbList: Control!$X$14:$X$16
Name SensitivityList: Control!$Y$14:$Y$17
Name ObjectTypeList: Control!$Z$14:$Z$19
Name ReviewThreshold: Control!$B$55
Name EventFamilyList: Control!$AA$14:$AA$19

Sheet Dashboard
A1: PublicLogic · PuddleJumper Runtime
A2: Artifact taxonomy + PuddleJumper observation layer · publish governed facts, not workflows
A4: Metric | B4: Value | C4: Signal | E4: Significance | F4: Count
A5: Artifacts | B5: =COUNTA('Artifact Registry'!B5:B200) | C5: =IF(B5>=1,"OK","CHECK") | E5: Info | F5: =COUNTIF('PJ Event Log'!L5:L200,"Info")
A6: Event Types | B6: =COUNTA(EventTypeList) | C6: =IF(B6=COUNTA(EventTypeList),"OK","CHECK") | E6: Watch | F6: =COUNTIF('PJ Event Log'!L5:L200,"Watch")
A7: Events Logged | B7: =COUNTA('PJ Event Log'!A5:A200) | C7: =IF(B7>=1,"OK","CHECK") | E7: Action | F7: =COUNTIF('PJ Event Log'!L5:L200,"Action")
A8: Validation Checks | B8: =COUNTA(Validation!A5:A50) | C8: =IF(COUNTIF(Validation!D5:D50,"CHECK")=0,"OK","CHECK") | E8: Critical | F8: =COUNTIF('PJ Event Log'!L5:L200,"Critical")
A9: Unresolved Critical Events | B9: =COUNTIFS('PJ Event Log'!L5:L200,"Critical",'PJ Event Log'!P5:P200,"No") | C9: =IF(B9=0,"OK","ACTION")
A10: Runtime Readiness | B10: =IF(AND(COUNTIF(Validation!D5:D50,"CHECK")=0,B9=0),"READY","NOT READY") | C10: =IF(B10="READY","OK","ACTION")
A13: Doctrine Rule | B13: Meaning
A14: Observe, do not own | B14: PJ never becomes the system of record.
A15: Publish governed facts | B15: Events report what happened, not what should happen.
A16: Consumers own behavior | B16: Notifications, dashboards, and archives subscribe independently.
A17: Identity delegated | B17: PJ does not own user passwords.
A18: Artifact ID is permanent | B18: IDs are typed, never derived. Never rely on filenames, paths, or URLs as identity.
A20: CASE LAYER
A21: Active case | B21: ='Case Overview'!B5
A22: Case lifecycle | B22: ='Case Overview'!B9
A23: Case artifacts | B23: ='Case Overview'!B16
A24: Case events | B24: ='Case Overview'!B17
A25: Closeout readiness | B25: ='Case Overview'!B25
A27: SIGNAL LAYER
A28: Signals received | B28: =COUNTA('Signal Intake'!A5:A60)
A29: Signals held for review | B29: =COUNTIF('Signal Intake'!L5:L60,"needs_review") | C29: =IF(B29=0,"OK","REVIEW")
A30: Open review items | B30: =COUNTIF('Review Queue'!M5:M40,"Open")
A31: Signals unpreserved | B31: =COUNTIFS('Signal Intake'!A5:A60,"<>",'Signal Intake'!N5:N60,"<>Yes") | C31: =IF(B31=0,"OK","ACTION")
A32: CONDITIONAL claims sealed | B32: =COUNTIFS('Artifact Registry'!Q5:Q200,"CONDITIONAL",'Artifact Registry'!G5:G200,"ARCHIEVE") | C32: =IF(B32=0,"OK","ACTION")
A34: CANON
A35: Vocabularies registered | B35: =COUNTA('Canon Registry'!A5:A20)
A36: Vocabulary drift vs code | B36: =COUNTIF('Canon Registry'!G5:G20,"DRIFT") | C36: =IF(B36=0,"OK","DRIFT")
A37: Canonical form version | B37: =Control!B56
A38: Review threshold | B38: =ReviewThreshold

Sheet README
A1: PublicLogic · PuddleJumper Runtime
A2: v3.0 CANON · governance + case surface + signal intake, grounded in golden-path source
A4: Purpose | B4: This workbook defines PublicLogic's artifact taxonomy, lifecycle doctrine, and PuddleJumper observation layer as a production-ready governance workbook.
A5: Core Rule | B5: Governance is the model; software is replaceable. PJ observes, normalizes, classifies, and publishes governed facts.
A6: Identity | B6: Delegated to upstream systems: Microsoft 365, Google Workspace, Azure AD, CivicPlus, GitHub.
A7: Artifacts | B7: Persistent Artifact ID + Family + Nature + Authority + Owner + Retention.
A8: Lifecycle | B8: FORM → CaseSpace → DocDump → ARCHIEVE.
A9: Events | B9: Small, closed vocabulary of governed facts; consumers decide behavior.
A10: v2.0 Changes | B10: Merged the CaseSpace starter into the governance canon. One Control block, one closed event vocabulary, one PRR (the PJ Event Log). Case ID added as a facet on both Artifact Registry and Event Log. Case FORM, evidence requests, and decisions are now registered artifacts with permanent IDs. "Sealed" retired in favour of ARCHIEVE. CAL and PRM expanded. Evidence requests gained owners, due dates, and a staleness check. Case closeout gate added. Append-only is documented as asserted, not enforced.
A11: Honest limitation | B11: Excel cannot enforce append-only immutability. The PuddleJumper runtime does, via trigger-enforced audit. This workbook is a working surface and a design artifact — it is never the system of record.
A12: v2.1 Changes | B12: Added the connector spine: Signal Intake and Review Queue. CANON CHANGE — the closed event vocabulary grew from 12 to 15 with SignalReceived, SignalHeldForReview, and SignalResolved. Added Claim Status (CONFIRMED / PENDING / PROJECTED / CONDITIONAL) as a facet on every artifact, and a gate preventing any CONDITIONAL claim from being sealed to ARCHIEVE.
A13: The refusal is the product | B13: A signal is placed only on match evidence. Absent it, the decision is needs_review: the signal is preserved, the missing evidence is recorded, and a person resolves it. The second receipt proves PJ did not guess and names who decided.
A14: v3.0 Changes | B14: Domain retired in favour of Lane, adopting LOCKED_LANES from golden-path/src/form.js — the workbook had six domains that do not exist in running code. Added PRR Kind, Receipt Verb, and Human Verb vocabularies, all lifted verbatim from source. REVIEW_THRESHOLD (0.6) and CANONICAL_FORM_VERSION (v1) mirrored as named constants and enforced: a signal below threshold must be held, a signal at or above it must not be. New Canon Registry sheet names one authoritative source per vocabulary and computes drift.
A15: The canon rule | B15: Code is canon for any vocabulary enforced at runtime. This workbook is canon for governance vocabularies code does not enforce. Everything else — website workbook, business stack, client briefs, repo READMEs — is a derived view that may cite canon and may never define it.
... A19: v3.3 Changes | B19: Adversarial testing found the drift check could not fail: appending a value below a named range, or renaming a member, both passed. Drift now requires count match AND exact ordered membership (SUMPRODUCT/EXACT against the source literal) AND an empty spill window below each range. TEXTJOIN was rejected — unavailable.

Sheet Architecture
A1: Four-Layer PublicLogic Architecture
A2: Each layer is independent and replaceable. PJ sits in the Event / Observation layer.
A4: Layer | B4: Question | C4: Owns | D4: Examples | E4: Does PJ Own It? | F4: Doctrine
A5: 1. Identity | B5: Who is acting? | C5: Upstream identity providers | D5: Microsoft 365, Google Workspace, Azure AD, CivicPlus, GitHub | E5: No | F5: Identity is delegated, never duplicated.
A6: 2. Artifacts | B6: What things are? | C6: PublicLogic taxonomy | D6: Family, Nature, Authority, Owner, Retention, Artifact ID | E6: No | F6: Artifacts are the unit of governance.
A7: 3. Lifecycle | B7: Where things are? | C7: Runtime doctrine | D7: FORM → CaseSpace → DocDump → ARCHIEVE | E7: No | F7: Lifecycle state is observable, not owned.
A8: 4. Events | B8: What changed? | C8: PuddleJumper Observation Layer | D8: Created, Modified, Approved, Archived, EvidenceGapDetected | E8: Yes | F8: Events describe facts, not intentions.
A11: Rule | B11: Principle | C11: Operational Test
A12: 1 | B12: Systems of record own truth. | C12: Can the source system remain authoritative if PJ is turned off?
A13: 2 | B13: Artifacts are the unit of governance. | C13: Does every governed object have one persistent Artifact ID?
A14: 3 | B14: Events describe facts, not intentions. | C14: Does each event state what happened, not what should happen?
A15: 4 | B15: Consumers own behavior. | C15: Can email, dashboard, and archive react independently?
A16: 5 | B16: Identity is delegated. | C16: Can PJ avoid owning user passwords and authentication?

Sheet Canon Registry
A1: Canon Registry — one canon, everything else cites it
A2: Each vocabulary has exactly one authoritative source. Code wins where code enforces. Drift? compares the count here against the count in the source.
A4: Vocabulary | B4: Named Range | C4: Count here | D4: Authoritative source | E4: Constant | F4: Count in source | G4: Drift? | H4: Owner | I4: Expected members (source) | J4: Members match? | K4: Spill guard
A5: Lane | B5: LaneList | C5: =COUNTA(LaneList) | D5: golden-path/src/form.js | E5: LOCKED_LANES | F5: 4 | G5: =IF(AND(C5=F5,OR(J5="n/a",J5="OK"),K5="OK"),"OK","DRIFT") | H5: Code | I5: STAY; MUNI; PROJECT; BIZ | J5: =IF(SUMPRODUCT(--EXACT(LaneList,{"STAY";"MUNI";"PROJECT";"BIZ"}))=4,"OK","DRIFT") | K5: =IF(COUNTA(Control!$B$18:$B$22)=0,"OK","SPILL")
A6: Signal Kind | B6: SignalKindList | C6: =COUNTA(SignalKindList) | D6: golden-path/src/signal.js | E6: SIGNAL_KINDS | F6: 8 | G6: =IF(AND(C6=F6,OR(J6="n/a",J6="OK"),K6="OK"),"OK","DRIFT") | H6: Code | I6: email; file; event; row; invoice; webhook; form; other | J6: =IF(SUMPRODUCT(--EXACT(SignalKindList,{"email";"file";"event";"row";"invoice";"webhook";"form";"other"}))=8,"OK","DRIFT") | K6: =IF(COUNTA(Control!$R$22:$R$26)=0,"OK","SPILL")
A7: Connector Type | B7: ConnectorTypeList | C7: =COUNTA(ConnectorTypeList) | D7: golden-path/src/signal.js | E7: CONNECTOR_TYPES | F7: 5 | G7: =IF(AND(C7=F7,OR(J7="n/a",J7="OK"),K7="OK"),"OK","DRIFT") | H7: Code | I7: files; api; db; web; local | J7: =IF(SUMPRODUCT(--EXACT(ConnectorTypeList,{"files";"api";"db";"web";"local"}))=5,"OK","DRIFT") | K7: =IF(COUNTA(Control!$Q$19:$Q$23)=0,"OK","SPILL")
A8: Decision | B8: DecisionList | C8: =COUNTA(DecisionList) | D8: golden-path/src/connector.js | E8: CASE_ACTIONS | F8: 4 | G8: =IF(AND(C8=F8,OR(J8="n/a",J8="OK"),K8="OK"),"OK","DRIFT") | H8: Code | I8: open; append; ignore; needs_review | J8: =IF(SUMPRODUCT(--EXACT(DecisionList,{"open";"append";"ignore";"needs_review"}))=4,"OK","DRIFT") | K8: =IF(COUNTA(Control!$S$18:$S$22)=0,"OK","SPILL")
A9: Receipt Verb | B9: ReceiptVerbList | C9: =COUNTA(ReceiptVerbList) | D9: golden-path/src/connector.js | E9: RECEIPT_VERB | F9: 4 | G9: =IF(AND(C9=F9,OR(J9="n/a",J9="OK"),K9="OK"),"OK","DRIFT") | H9: Code | I9: opened_casespace; appended_to_casespace; flagged_for_review; ignored | J9: =IF(SUMPRODUCT(--EXACT(ReceiptVerbList,{"opened_casespace";"appended_to_casespace";"flagged_for_review";"ignored"}))=4,"OK","DRIFT") | K9: =IF(COUNTA(Control!$W$18:$W$22)=0,"OK","SPILL")
A10: Human Verb | B10: HumanVerbList | C10: =COUNTA(HumanVerbList) | D10: golden-path/src/review.js | E10: HUMAN_VERB | F10: 3 | G10: =IF(AND(C10=F10,OR(J10="n/a",J10="OK"),K10="OK"),"OK","DRIFT") | H10: Code | I10: human_appended_to_casespace; human_opened_casespace; human_ignored_signal | J10: =IF(SUMPRODUCT(--EXACT(HumanVerbList,{"human_appended_to_casespace";"human_opened_casespace";"human_ignored_signal"}))=3,"OK","DRIFT") | K10: =IF(COUNTA(Control!$X$17:$X$21)=0,"OK","SPILL")
A11: Resolution | B11: ResolutionList | C11: =COUNTA(ResolutionList) | D11: golden-path/src/review.js | E11: HUMAN_VERB (keys) | F11: 3 | G11: =IF(AND(C11=F11,OR(J11="n/a",J11="OK"),K11="OK"),"OK","DRIFT") | H11: Code | I11: append; open; ignore | J11: =IF(SUMPRODUCT(--EXACT(ResolutionList,{"append";"open";"ignore"}))=3,"OK","DRIFT") | K11: =IF(COUNTA(Control!$T$17:$T$21)=0,"OK","SPILL")
A12: PRR Kind | B12: PRRKindList | C12: =COUNTA(PRRKindList) | D12: golden-path/src/prr.js | E12: PRR_KINDS | F12: 8 | G12: =IF(AND(C12=F12,OR(J12="n/a",J12="OK"),K12="OK"),"OK","DRIFT") | H12: Code | I12: FORM; EVIDENCE; DECISION; CAL; PRM; TIME; NOTE; SEAL | J12: =IF(SUMPRODUCT(--EXACT(PRRKindList,{"FORM";"EVIDENCE";"DECISION";"CAL";"PRM";"TIME";"NOTE";"SEAL"}))=8,"OK","DRIFT") | K12: =IF(COUNTA(Control!$V$22:$V$26)=0,"OK","SPILL")
A13: Lifecycle | B13: LifecycleList | C13: =COUNTA(LifecycleList) | D13: This workbook | E13: Control!D14:D17 | F13: 4 | G13: =IF(AND(C13=F13,OR(J13="n/a",J13="OK"),K13="OK"),"OK","DRIFT") | H13: Workbook | J13: n/a | K13: =IF(COUNTA(Control!$D$18:$D$22)=0,"OK","SPILL")
A14: Artifact Family | B14: FamilyList | C14: =COUNTA(FamilyList) | D14: This workbook | E14: Taxonomy sheet | F14: 10 | G14: =IF(AND(C14=F14,OR(J14="n/a",J14="OK"),K14="OK"),"OK","DRIFT") | H14: Workbook | J14: n/a | K14: =IF(COUNTA(Control!$E$24:$E$28)=0,"OK","SPILL")
A15: Artifact Event | B15: EventTypeList | C15: =COUNTA(EventTypeList) | D15: This workbook (Event Vocabulary sheet) | E15: Closed Event Vocabulary | F15: 15 | G15: =IF(AND(C15=F15,OR(J15="n/a",J15="OK"),K15="OK"),"OK","DRIFT") | H15: Workbook | J15: n/a | K15: =IF(COUNTA(Control!$F$29:$F$33)=0,"OK","SPILL")
A16: Nature | B16: NatureList | C16: =COUNTA(NatureList) | D16: This workbook | E16: Control!C14:C15 | F16: 2 | G16: =IF(AND(C16=F16,OR(J16="n/a",J16="OK"),K16="OK"),"OK","DRIFT") | H16: Workbook | J16: n/a | K16: =IF(COUNTA(Control!$C$16:$C$20)=0,"OK","SPILL")
A17: Significance | B17: SignificanceList | C17: =COUNTA(SignificanceList) | D17: This workbook | E17: Control!H14:H17 | F17: 4 | G17: =IF(AND(C17=F17,OR(J17="n/a",J17="OK"),K17="OK"),"OK","DRIFT") | H17: Workbook | J17: n/a | K17: =IF(COUNTA(Control!$H$18:$H$22)=0,"OK","SPILL")
A18: Status | B18: StatusList | C18: =COUNTA(StatusList) | D18: This workbook | E18: Control!G14:G21 | F18: 8 | G18: =IF(AND(C18=F18,OR(J18="n/a",J18="OK"),K18="OK"),"OK","DRIFT") | H18: Workbook | J18: n/a | K18: =IF(COUNTA(Control!$G$22:$G$26)=0,"OK","SPILL")
A19: Risk | B19: RiskList | C19: =COUNTA(RiskList) | D19: This workbook | E19: Control!K14:K16 | F19: 3 | G19: =IF(AND(C19=F19,OR(J19="n/a",J19="OK"),K19="OK"),"OK","DRIFT") | H19: Workbook | J19: n/a | K19: =IF(COUNTA(Control!$K$17:$K$21)=0,"OK","SPILL")
A20: Claim Status | B20: ClaimStatusList | C20: =COUNTA(ClaimStatusList) | D20: Capabilities Brief (VAULT method) | E20: Claims discipline | F20: 4 | G20: =IF(AND(C20=F20,OR(J20="n/a",J20="OK"),K20="OK"),"OK","DRIFT") | H20: Workbook | J20: n/a | K20: =IF(COUNTA(Control!$U$18:$U$22)=0,"OK","SPILL")
A21: Sensitivity | B21: SensitivityList | C21: =COUNTA(SensitivityList) | D21: This workbook (governance vocabulary; no runtime enforces it) | E21: sensitivity_level | F21: 4 | G21: =IF(AND(C21=F21,OR(J21="n/a",J21="OK"),K21="OK"),"OK","DRIFT") | H21: Workbook | I21: public; internal; restricted; confidential | J21: =IF(SUMPRODUCT(--EXACT(SensitivityList,{"public";"internal";"restricted";"confidential"}))=4,"OK","DRIFT") | K21: =IF(COUNTA(Control!$Y$18:$Y$22)=0,"OK","SPILL")
A22: Object Type | B22: ObjectTypeList | C22: =COUNTA(ObjectTypeList) | D22: LogicOS Build Spec v3 §1.1 | E22: Record/Case/Task/… | F22: 6 | G22: =IF(AND(C22=F22,OR(J22="n/a",J22="OK"),K22="OK"),"OK","DRIFT") | H22: Workbook | J22: n/a | K22: =IF(COUNTA(Control!$Z$20:$Z$24)=0,"OK","SPILL")
A23: Event Family | B23: EventFamilyList | C23: =COUNTA(EventFamilyList) | D23: golden-path/src/audit.js | E23: AUDIT_EVENT_FAMILIES | F23: 6 | G23: =IF(AND(C23=F23,OR(J23="n/a",J23="OK"),K23="OK"),"OK","DRIFT") | H23: Code | I23: process; transition; role; auth; divergence; system | J23: =IF(SUMPRODUCT(--EXACT(EventFamilyList,{"process";"transition";"role";"auth";"divergence";"system"}))=6,"OK","DRIFT") | K23: =IF(COUNTA(Control!$AA$20:$AA$24)=0,"OK","SPILL")
A24: ARCHIEVE Event Family Map | D24: puddlejumper canon.json (ArchieveEventTypeValue -> AuditEventFamily) | E24: ARCHIEVE_EVENT_FAMILY | G24: UNVERIFIABLE | H24: Code (puddlejumper) | I24: cross-repo — human-approved map, revision-pinned
A25: DERIVED VIEWS — may cite canon, may never define it
A26: Artifact | B26: May define | C26: Must cite | D26: Drift risk
A27: PublicLogic_Website_Workbook_FINAL_LOCKED.xlsx | B27: Brand, pricing, hero copy | C27: VAULT wording; "runtime not engine" | D27: High — asserts canon it does not own
A28: Move Forward — v1 Business Stack.docx | B28: Offer ladder, tiers, 90-day plan | C28: Nothing operational | D28: Low
A29: Capabilities & Opportunity Brief (Timber Logistics) | B29: Client-specific findings | C29: VAULT; Claim Status vocabulary | D29: Medium — originated Claim Status; now canon here
A30: github.com/97n8/lab · packages/golden-path | B30: Runtime-enforced vocabularies (see above) | C30: Nothing — this IS canon for those | D30: None. Code is canon.
A31: github.com/97n8/lab · publiclogic web | B31: Site structure, SEO, routes | C31: Brand + canon guardrails from the Website Workbook | D31: Medium — README restates canon inline
A32: github.com/97n8/puddlejumper (private) | B32: Unknown — not auditable from here | C32: Everything above | D32: Unassessed
A35: Open question: PJ's own product artifacts (e.g. the Event Envelope) have no lane in LOCKED_LANES. They are mapped to PROJECT here. Either add a PRODUCT lane in code or accept the mapping — but decide, and record the decision.
A36: SUPERSEDED
A37: LogicOS Master Build Spec v3.0 (Apr 2026) | B37: Nothing — brand retired | C37: Object model, hierarchy, enforcement boundary, sensitivity survive; harvested into canon | D37: High — names LogicOS as product and PJ as backend control plane. Both false now.
A38: LogicOS / LogicDash / LogicSuite / Syncronate | B38: Nothing | C38: Retired names | D38: Do not reintroduce
A39: governanceEngine, chainStore | B39: Nothing | C39: Retired — and "engine" violates canon | D39: Runtime, never engine
A42: DERIVED VIEWS — batch 2
A43: VAULT Master Build Spec v0.02 | B43: Nothing | C43: VAULT doctrine | D43: CRITICAL — redefines VAULT with different pillars
A44: SYNCHRON8 Build Spec v1.1 | B44: Nothing | C44: Everything | D44: CRITICAL — "engine"; depends on prohibited n8n + killed AXIS
A45: LOGICBRIDGE Build Spec v1.0 | B45: Nothing | C45: Connector contract | D45: HIGH — superseded by golden-path connector.js
...

Sheet Canon Collisions
A1: Canon Collisions — DECISION REQUIRED
A2: Six documents claim canon authority over the same four terms and disagree. Nothing below is resolved. A term with more than one live definition has no definition.
A4: Term | B4: Claimed definition | C4: Source document | D4: Dated | E4: Conflicts with standing canon?
A5: VAULT | B5: Doctrine acronym: Verification · Authority · Utility · Legitimacy · Transfer | C5: Standing canon (Nate, authored) | D5: — | E5: BASELINE
A6: VAULT | B6: Governance architecture. Four Pillars: Authority, Accountability, Boundary, Continuity. Not an acronym. | C6: VAULT Master Build Spec v0.02 | D6: Mar 2026 | E6: YES — different letters, and Accountability is explicitly not canon
A7: VAULT | B7: Doctrine: Verified, Authorized, Utility, Legitimate, Transfer. Plus "Vault" as a product surface. | C7: LogicOS Master Build Spec v3.0 | D7: Apr 2026 | E7: YES — wording drift + overloads the name
A8: VAULT | B8: The Continuity Infrastructure: capture, storage, preservation, retrieval, governance. | C8: PublicLogic Canon 5-Page v1.0 | D8: — | E8: YES — infrastructure, not doctrine
A9: VAULT | B9: A runtime namespace/module inside the PJ container. | C9: PuddleJumper Build Spec v1.0 | D9: — | E9: YES — a module, not doctrine
A11: PuddleJumper | B11: Governance Process Runtime. The product. Never "engine." | C11: Standing canon | D11: — | E11: BASELINE
A12: PuddleJumper | B12: LogicSuite Runtime Platform. Monolith on Fly.io housing VAULT, ARCHIEVE, SEAL, AXIS, SYNCHRON8, LOGICBRIDGE, SYNCRONATE, FormKey, Module Maker. | C12: PuddleJumper Build Spec v1.0 | D12: — | E12: YES — subordinate to LogicSuite
A13: PuddleJumper | B13: Control Plane · Governed AI Assistant · Workflow Engine · Workspace Manager · AI Connector | C13: PuddleJumper Concept Spec v1.2 | D13: Apr 2026 | E13: YES — uses "engine"
A14: PuddleJumper | B14: Backend control plane. Never seen by operators or residents. LogicOS is the product. | C14: LogicOS Master Build Spec v3.0 | D14: Apr 2026 | E14: YES — PJ is not the product
A15: PuddleJumper | B15: The Stewardship Platform: onboarding, deployment, configuration, reviews, sustainment. | C15: PublicLogic Canon 5-Page v1.0 | D15: — | E15: YES — a services platform, not a runtime
A17: ARCHIEVE | B17: Seal/stamp execution layer. | C17: Standing canon | D17: — | E17: BASELINE
... A41: Permit & Bridge | B41: Not to be confused with LOGICBRIDGE (connector builder). Unrelated. | C41: — | D41: — | E41: Naming hazard
A44: DECISIONS REQUIRED
A45: 1. | B45: Is VAULT doctrine (an acronym) or infrastructure (a module)? It cannot be both. If doctrine: retire "Vault" as a product surface name.
A46: 2. | B46: Does VAULT contain Authority or Accountability? The VAULT Build Spec says Accountability. The site README says Authority, not Accountability.
A47: 3. | B47: Is PuddleJumper the product, or a backend control plane beneath LogicOS? LogicOS is retired — so PJ is the product. Confirm and kill the four contradicting specs.
A48: 4. | B48: Is ARCHIEVE a rules engine, a seal layer, or a lifecycle state? Currently all three.
A49: 5. | B49: Does the "never engine" rule apply retroactively? Four specs use it, including as component names (governanceEngine, chainStore).
A50: 6. | B50: n8n: prohibited, or a SYNCHRON8 dependency via AXIS? Both are written down.
A51: 7. | B51: AXIS, Module Maker, LogicSuite: killed, or load-bearing? PuddleJumper Build Spec cannot run without them.
A52: 8. | B52: Which connector layer is canon: LOGICBRIDGE, Syncronate, or golden-path connector.js? Only one is running code.
A53: 9. | B53: LogicCommons: killed route, shipped runtime, or free-template tier? Two of these need new names.
A54: 10. | B54: Do the Build Specs describe TARGET STATE or CURRENT STATE? Three say target state explicitly. Target state is not canon — it is a proposal.
A56: NOT CANON — no reconciliation needed
A57: Boudreau_Erving_90-Day_Framework_v6.pdf | B57: Job application artifact. Names no PublicLogic product. Nothing to reconcile.
A58: PublicLogic_Cyclical_Services_Model.xlsx | B58: Services and funding model. May define the cycle and cost treatment; defines no operational vocabulary. Cites VAULT and CaseSpace — must cite, not define.
A60: NOTE: SYNCHRON8 Build Spec names its repository as 97n8/puddlejumper · src/modules/synchron8/. That repo is private and could not be audited. It defines vocabularies. Until it is read, this registry is incomplete.

Sheet Control
A1: Control
A2: Named configuration, edition gates, and controlled vocabularies
A4: Workbook Edition | B4: Duo | C4: Single / Duo / Team
A5: Current Runtime | B5: PuddleJumper | C5: Observation layer
A6: Primary Doctrine | B6: Observe, do not own | C6: PJ publishes governed facts
A7: Default Lifecycle | B7: CaseSpace | C7: FORM / CaseSpace / DocDump / ARCHIEVE
A8: Default Nature | B8: Template | C8: Template / Instance
A9: Event Vocabulary Mode | B9: Closed | C9: Closed vocabulary unless canon changes
A13: Editions | B13: Lane | C13: Nature | D13: Lifecycle | E13: ArtifactFamily | F13: EventTypes | G13: Statuses | H13: Significance | I13: Sources | J13: Consumers | K13: Risk | L13: Resolved | M13: TaskStatus | N13: EvidenceStatus | O13: YesNo | P13: Cases | Q13: ConnectorType | R13: SignalKind | S13: Decision | T13: Resolution | U13: ClaimStatus | V13: PRRKind | W13: ReceiptVerb | X13: HumanVerb | Y13: Sensitivity | Z13: ObjectType | AA13: EventFamilies
A14: Single | B14: STAY | C14: Template | D14: FORM | E14: Intake & Authorization | F14: ArtifactCreated | G14: Draft | H14: Info | I14: Excel Workbook | J14: CaseSpace | K14: Low | L14: No | M14: Not started | N14: Requested | O14: Yes | P14: CS-2026-01 | Q14: files | R14: email | S14: open | T14: append | U14: CONFIRMED | V14: FORM | W14: opened_casespace | X14: human_appended_to_casespace | Y14: public | Z14: Record | AA14: process
A15: Duo | B15: MUNI | C15: Instance | D15: CaseSpace | E15: Source & Evidence | F15: ArtifactModified | G15: Active | H15: Watch | I15: GitHub | J15: ARCHIEVE | K15: Medium | L15: Yes | M15: In progress | N15: Received | O15: No | Q15: api | R15: file | S15: append | T15: open | U15: PENDING | V15: EVIDENCE | W15: appended_to_casespace | X15: human_opened_casespace | Y15: internal | Z15: Case | AA15: transition
A16: Team | B16: PROJECT | D16: DocDump | E16: Working Coordination | F16: ArtifactValidated | G16: Built | H16: Action | I16: Google Workspace | J16: Email Alerts | K16: High | M16: Done | N16: Waived | Q16: db | R16: event | S16: ignore | T16: ignore | U16: PROJECTED | V16: DECISION | W16: flagged_for_review | X16: human_ignored_signal | Y16: restricted | Z16: Task | AA16: role
B17: BIZ | D17: ARCHIEVE | E17: Analysis & Modeling | F17: ArtifactApproved | G17: Spec | H17: Critical | I17: Microsoft 365 | J17: Slack/Teams | M17: Blocked | Q17: web | R17: row | S17: needs_review | U17: CONDITIONAL | V17: CAL | W17: ignored | Y17: confidential | Z17: OrgNode | AA17: auth
E18: Recommendation & Decision | F18: ArtifactIssued | G18: Validated | I18: CivicPlus | J18: Dashboard | Q18: local | R18: invoice | V18: PRM | Z18: Alert | AA18: divergence
E19: Plans & Commitments | F19: ArtifactTransferred | G19: Approved | I19: CaseSpace | J19: Audit Log | R19: webhook | V19: TIME | Z19: EvidencePackage | AA19: system
E20: Operating Guidance | F20: ArtifactArchived | G20: Archived | I20: ARCHIEVE | R20: form | V20: NOTE
E21: Communications | F21: LifecycleAdvanced | G21: Exception | R21: other | V21: SEAL
E22: Transaction & Compliance | F22: RetentionTriggered
E23: Closeout & Memory | F23: EvidenceGapDetected
F24: AuthorityChanged
F25: ModuleReady
F26: SignalReceived
F27: SignalHeldForReview
A28: Artifact ID Grammar | F28: SignalResolved
A29: Pattern | B29: PL-{DOMAIN}-{MODULE}-{YYYY}-{NNNNN} | D29: Regex: ^PL-[A-Z]{2,5}-[A-Z0-9]{2,8}-\d{4}-\d{5}$
A30: Assignment | B30: Manual, sequential, from the module counter | D30: IDs are typed, never derived by formula.
A31: Immutability | B31: An Artifact ID is never changed or reused | D31: Re-filing or renaming an artifact does not alter its ID.
A32: Prohibited | B32: No formula, no TODAY(), no ROW() | D32: Derived IDs mutate when their inputs mutate. That is not identity.
A33: Retired IDs | B33: Mark superseded; never delete or reissue | D33: Historical events must remain resolvable.
A36: Canon Note | B36: This workbook uses the FUNCTIONAL 10-family taxonomy (organized by the work an artifact does). It is the governing canon. Any formal artifact-type vocabulary (Agreement, Specification, Register, Record) is a subtype layer beneath Family, not a competing top-level axis.
A37: Citation Canon | B37: Massachusetts general laws: M.G.L. c. NN, § NN. Federal regulations: N C.F.R. § NNN. Non-statutory authority is written in plain language (e.g. "Internal operating policy", "PublicLogic canon").
A38: Case Layer Doctrine
A39: One PRR | B39: The PJ Event Log IS the recordstream. A CaseSpace does not keep a second event log.
A40: Case ID is a facet | B40: Case ID tags artifacts and events. It is not a lifecycle state and not an artifact type.
A41: Every case object is an artifact | B41: FORMs, evidence requests, and decisions are registered artifacts with permanent IDs.
A42: Append-only is asserted, not enforced | B42: Excel cannot enforce immutability. The runtime does. This workbook is a working surface, never the system of record.
A43: Sealed = ARCHIEVE | B43: A case is sealed when its lifecycle reaches ARCHIEVE and no PRM item blocks closeout.
A45: Signal Intake Doctrine
A46: Signal in, receipt out | B46: Every inbound artifact becomes a governed object and earns a receipt. No exceptions, including held signals.
A47: PJ does not guess | B47: Without sufficient match evidence the decision is needs_review. A held signal is preserved, never discarded and never falsely placed.
...

Sheet Taxonomy
A1: 10-Family Artifact Taxonomy
A2: Artifact type is separate from lifecycle. Nature separates blueprints from filled documents.
A4: Family | B4: Plain-English Role | C4: Examples | D4: Typical Events | E4: Default Retention
A5: Intake & Authorization | B5: Starts work and confirms permission | C5: Intake form, authorization, acknowledgment | D5: ArtifactCreated, ArtifactApproved | E5: Standard 3-7y
A6: Source & Evidence | B6: Stores source material and proof | C6: Email, signed letter, uploaded file, citation packet | D6: ArtifactCreated, EvidenceGapDetected | E6: Long 7-30y
A7: Working Coordination | B7: Keeps active work moving | C7: Tracker, minutes, task list, coordination log | D7: ArtifactModified, LifecycleAdvanced | E7: Standard 3-7y
A8: Analysis & Modeling | B8: Turns inputs into insight | C8: Budget model, GHG model, scoring sheet | D8: ArtifactValidated, ArtifactModified | E8: Long 7-30y
A9: Recommendation & Decision | B9: Supports or records choices | C9: Decision memo, findings, approval certificate | D9: ArtifactApproved, ArtifactIssued | E9: Permanent
A10: Plans & Commitments | B10: Sets intended action or obligation | C10: SOP, runbook, playbook, checklist | D10: ArtifactApproved, ArtifactIssued | E10: Long 7-30y
A11: Operating Guidance | B11: Helps people run the system | C11: Cover memo, public notice, transmittal, slide deck | D11: ArtifactModified, ModuleReady | E11: Current + prior
A12: Communications | B12: Explains or transmits information | C12: Email, cover memo, public notice, slide deck | D12: ArtifactIssued, ArtifactModified | E12: Standard 3-7y
A13: Transaction & Compliance | B13: Completes governed transactions | C13: Invoice, grant report, procurement file, W-9 | D13: ArtifactValidated, ArtifactArchived | E13: Long 7-30y
A14: Closeout & Memory | B14: Preserves final state and transfer memory | C14: Closeout memo, ARCHIEVE snapshot, transfer packet | D14: ArtifactArchived, ArtifactTransferred | E14: Permanent
A15: Note | B15: Retention labels are planning bands, not legal schedules. Municipal artifacts must be mapped to a specific series in the Massachusetts Municipal Records Retention Schedule before disposition.

Sheet Event Vocabulary
A1: Closed Event Vocabulary
A2: PJ publishes facts using a small, governed vocabulary. Add events only by canon change.
A4: Event Type | B4: Definition | C4: Allowed Trigger | D4: Primary Metadata | E4: Default Significance | F4: Consumer Examples
A5: ArtifactCreated | B5: A new governed artifact has entered the system. | C5: New artifact record or source object detected. | D5: artifact_id, family, nature, lifecycle, owner | E5: Info | F5: Dashboard, Audit Log
A6: ArtifactModified | B6: An existing artifact changed. | C6: Content, metadata, or version changed. | D6: artifact_id, version, source_system | E6: Watch | F6: Dashboard
A7: ArtifactValidated | B7: Artifact passed a governance check. | C7: Validation status moved to Validated. | D7: artifact_id, validation_rule, owner | E7: Info | F7: Audit Log, CaseSpace
A8: ArtifactApproved | B8: Artifact received formal approval. | C8: Approval field/signature/status applied. | D8: artifact_id, approver, authority | E8: Action | F8: Email, Audit Log
A9: ArtifactIssued | B9: Artifact was sent to client/public/recipient. | C9: Issued/sent/published status detected. | D9: artifact_id, recipient, timestamp | E9: Action | F9: Email, ARCHIEVE
A10: ArtifactTransferred | B10: Artifact moved to a new owner/steward. | C10: Owner changed or transfer packet created. | D10: artifact_id, from_owner, to_owner | E10: Action | F10: CaseSpace
A11: ArtifactArchived | B11: Artifact entered ARCHIEVE. | C11: Lifecycle transitioned to ARCHIEVE. | D11: artifact_id, archive_path, retention | E11: Info | F11: ARCHIEVE, Audit Log
A12: LifecycleAdvanced | B12: Artifact moved to a next lifecycle state. | C12: FORM→CaseSpace or CaseSpace→DocDump etc. | D12: artifact_id, old_lifecycle, new_lifecycle | E12: Watch | F12: Dashboard, CaseSpace
A13: RetentionTriggered | B13: Retention clock started/completed/review due. | C13: Lifecycle or date condition activates retention. | D13: artifact_id, retention, trigger_date | E13: Watch | F13: Audit Log
A14: EvidenceGapDetected | B14: Required evidence is missing. | C14: Validation or completeness check failed. | D14: artifact_id, missing_evidence, due_by | E14: Critical | F14: Email, Dashboard
A15: AuthorityChanged | B15: Governing citation/policy changed. | C15: Authority metadata updated. | D15: artifact_id, old_authority, new_authority | E15: Action | F15: Audit Log, Email
... A19: SignalResolved | B19: A person resolved a held signal by appending, opening, or ignoring. | C19: Review item resolved. | D19: signal_id, prior_receipt_id, resolved_by, action | E19: Action | F19: Audit Log

Sheet Event Envelope
A1: Canonical PJ Event Envelope
A2: Every event has the same schema so consumers subscribe to facts, not source-specific details.
A4: Field | B4: Required | C4: Type | D4: Example | E4: Governance Rule
A5: event_id | B5: Yes | C5: String | D5: EVT-2026-000001 | E5: Unique event ID, immutable after publish.
A6: timestamp | B6: Yes | C6: ISO datetime | D6: 2026-07-09T09:00:00-04:00 | E6: Use source timestamp if trustworthy; otherwise observation timestamp.
A7: event_type | B7: Yes | C7: Controlled value | D7: ArtifactArchived | E7: Must exist in Event Vocabulary.
A8: artifact_id | B8: Yes | C8: String | D8: PL-GRANT-GRNT-2026-00008 | E8: Never use filename/path as primary identity.
A9: family | B9: Yes | C9: Controlled value | D9: Transaction & Compliance | E9: Must exist in Taxonomy.
A10: nature | B10: Yes | C10: Template/Instance | D10: Instance | E10: Separates blueprint from filled work product.
A11: lifecycle | B11: Yes | C11: Controlled value | D11: ARCHIEVE | E11: FORM, CaseSpace, DocDump, ARCHIEVE.
A12: owner | B12: Yes | C12: Text | D12: Grant Manager | E12: Person/role responsible for artifact stewardship.
A13: authority | B13: Recommended | C13: Text | D13: 2 CFR 200 | E13: Governing citation, policy, contract, or canon.
A14: source_system | B14: Yes | C14: Controlled value | D14: Microsoft 365 | E14: Where the event was observed.
A15: version | B15: Recommended | C15: String | D15: v1.2 | E15: Version at time of event.
A16: metadata | B16: Optional | C16: JSON object | D16: {"old":"CaseSpace","new":"ARCHIEVE"} | E16: Source-specific details; never required for core interpretation.

Sheet Artifact Registry
A1: Artifact Registry
A2: Governed objects with persistent Artifact IDs. Never depend on filenames, paths, or URLs as identity.
A3: Artifact IDs are typed manually and are immutable. Grammar: PL-{DOMAIN}-{MODULE}-{YYYY}-{NNNNN}. See Control!A28. Never formula-derive an ID.
A4: Artifact ID | B4: Artifact Name | C4: Module | D4: Lane | E4: Family | F4: Nature | G4: Lifecycle | H4: Authority | I4: Owner | J4: Retention | K4: Version | L4: Status | M4: Source System | N4: Last Event | O4: Risk | P4: Case ID | Q4: Claim Status | R4: Sensitivity
A5: PL-MUNI-PRR-2026-00142 | B5: PRR Acknowledgment Template | C5: PRR | D5: MUNI | E5: Intake & Authorization | F5: Template | G5: CaseSpace | H5: M.G.L. c. 66, § 10 | I5: Records Access Officer | J5: Permanent | K5: v1.0 | L5: Built | M5: Excel Workbook | N5: ArtifactValidated | O5: Low | Q5: CONFIRMED | R5: public
A6: PL-GRANT-GRNT-2026-00008 | B6: Grant Report Package | C6: Grants | D6: PROJECT | E6: Transaction & Compliance | F6: Instance | G6: ARCHIEVE | H6: 2 C.F.R. § 200 | I6: Grant Manager | J6: Long 7-30y | K6: v1.2 | L6: Archived | M6: Microsoft 365 | N6: ArtifactArchived | O6: Low | Q6: CONFIRMED | R6: restricted
A7: PL-BIZ-HIRE-2026-00017 | B7: Offer Letter Template | C7: Hiring & Onboarding | D7: BIZ | E7: Transaction & Compliance | F7: Template | G7: CaseSpace | H7: I-9 / W-4 / personnel file | I7: Operations Lead | J7: Standard 3-7y | K7: v0.8 | L7: Spec | M7: Excel Workbook | N7: ArtifactModified | O7: Medium | Q7: PENDING | R7: confidential
A8: PL-STAY-OPS-2026-00003 | B8: Kendall Pond Turnover Checklist | C8: STAY Operations | D8: STAY | E8: Operating Guidance | F8: Instance | G8: CaseSpace | H8: Internal operating policy | I8: Property Lead | J8: Current + prior | K8: v1.1 | L8: Active | M8: Google Workspace | N8: LifecycleAdvanced | O8: Low | P8: CS-2026-01 | Q8: CONFIRMED | R8: internal
A9: PL-MUNI-PROC-2026-00021 | B9: IFB/RFP Shell | C9: Procurement | D9: MUNI | E9: Plans & Commitments | F9: Template | G9: DocDump | H9: M.G.L. c. 30B | I9: Procurement Officer | J9: Long 7-30y | K9: v0.5 | L9: Spec | M9: Excel Workbook | N9: EvidenceGapDetected | O9: High | Q9: CONDITIONAL | R9: internal
A10: PL-PROD-PJ-2026-00001 | B10: PuddleJumper Event Envelope | C10: PuddleJumper | D10: PROJECT | E10: Operating Guidance | F10: Template | G10: ARCHIEVE | H10: PublicLogic canon | I10: Product Owner | J10: Permanent | K10: v1.0 | L10: Validated | M10: GitHub | N10: ModuleReady | O10: Low | Q10: CONFIRMED | R10: internal
A11: PL-STAY-CASE-2026-00001 | B11: CS-2026-01 Intake FORM | C11: CaseSpace | D11: STAY | E11: Intake & Authorization | F11: Instance | G11: FORM | H11: Internal operating policy | I11: Property Lead | J11: Standard 3-7y | K11: v1.0 | L11: Active | M11: Excel Workbook | N11: ArtifactCreated | O11: Low | P11: CS-2026-01 | Q11: CONFIRMED | R11: internal
A12: PL-STAY-CASE-2026-00002 | B12: Evidence Request: 06-15 turnover photos | C12: CaseSpace | D12: STAY | E12: Source & Evidence | F12: Instance | G12: DocDump | H12: Internal operating policy | I12: Property Lead | J12: Standard 3-7y | K12: v1.0 | L12: Exception | M12: Google Workspace | N12: EvidenceGapDetected | O12: High | P12: CS-2026-01 | Q12: PENDING | R12: internal
A13: PL-STAY-CASE-2026-00003 | B13: Decision: view-only guestbook, no PMS | C13: CaseSpace | D13: STAY | E13: Recommendation & Decision | F13: Instance | G13: CaseSpace | H13: Internal operating policy | I13: Property Lead | J13: Permanent | K13: v1.0 | L13: Approved | M13: Excel Workbook | N13: ArtifactApproved | O13: Low | P13: CS-2026-01 | Q13: CONFIRMED | R13: internal
A14: PL-STAY-SIG-2026-00001 | B14: Held signal: guest check-in question | C14: CaseSpace | D14: STAY | E14: Source & Evidence | F14: Instance | G14: FORM | H14: Internal operating policy | I14: Property Lead | J14: Standard 3-7y | K14: v1.0 | L14: Exception | M14: Google Workspace | N14: SignalHeldForReview | O14: Low | Q14: PENDING | R14: internal

Sheet PJ Event Log
A1: PuddleJumper Event Log
A2: Pattern-smart observation layer: observed source changes normalized into governed facts.
A4: Event ID | B4: Timestamp | C4: Event Type | D4: Artifact ID | E4: Family | F4: Nature | G4: Lifecycle | H4: Owner | I4: Authority | J4: Source System | K4: Version | L4: Significance | M4: Consumer | N4: Metadata | O4: Valid? | P4: Resolved | Q4: Case ID | R4: PRR Kind
A5: EVT-2026-000001 | B5: 46212.375 | C5: ArtifactValidated | D5: PL-MUNI-PRR-2026-00142 | E5: Intake & Authorization | F5: Template | G5: CaseSpace | H5: Records Access Officer | I5: M.G.L. c. 66, § 10 | J5: Excel Workbook | K5: v1.0 | L5: Info | M5: Audit Log | N5: {"rule":"authority_present"} | O5: =IF(A5="","",IF(AND(COUNTIF(EventTypeList,C5)>0,COUNTIF('Artifact Registry'!$A$5:$A$200,D5)>0,COUNTIF(FamilyList,E5)>0,COUNTIF(NatureList,F5)>0,COUNTIF(LifecycleList,G5)>0,COUNTIF(SignificanceList,L5)>0,COUNTIF(ConsumerList,M5)>0),"PASS","CHECK")) | P5: No | R5: NOTE
A6: EVT-2026-000002 | B6: 46212.383 | C6: ArtifactArchived | D6: PL-GRANT-GRNT-2026-00008 | E6: Transaction & Compliance | F6: Instance | G6: ARCHIEVE | H6: Grant Manager | I6: 2 C.F.R. § 200 | J6: Microsoft 365 | K6: v1.2 | L6: Info | M6: ARCHIEVE | N6: {"old_lifecycle":"CaseSpace","new_lifecycle":"ARCHIEVE"} | O6: =IF(A6="","",IF(AND(COUNTIF(EventTypeList,C6)>0,COUNTIF('Artifact Registry'!$A$5:$A$200,D6)>0,COUNTIF(FamilyList,E6)>0,COUNTIF(NatureList,F6)>0,COUNTIF(LifecycleList,G6)>0,COUNTIF(SignificanceList,L6)>0,COUNTIF(ConsumerList,M6)>0),"PASS","CHECK")) | P6: No | R6: SEAL
A7: EVT-2026-000003 | B7: 46212.39 | C7: EvidenceGapDetected | D7: PL-MUNI-PROC-2026-00021 | E7: Plans & Commitments | F7: Template | G7: DocDump | H7: Procurement Officer | I7: M.G.L. c. 30B | J7: Excel Workbook | K7: v0.5 | L7: Critical | M7: Email Alerts | N7: {"missing":"COI certification"} | O7: =IF(A7="","",IF(AND(COUNTIF(EventTypeList,C7)>0,COUNTIF('Artifact Registry'!$A$5:$A$200,D7)>0,COUNTIF(FamilyList,E7)>0,COUNTIF(NatureList,F7)>0,COUNTIF(LifecycleList,G7)>0,COUNTIF(SignificanceList,L7)>0,COUNTIF(ConsumerList,M7)>0),"PASS","CHECK")) | P7: No | R7: EVIDENCE
A8: EVT-2026-000004 | B8: 46212.398 | C8: ModuleReady | D8: PL-PROD-PJ-2026-00001 | E8: Operating Guidance | F8: Template | G8: ARCHIEVE | H8: Product Owner | I8: PublicLogic canon | J8: GitHub | K8: v1.0 | L8: Info | M8: Dashboard | N8: {"module":"PuddleJumper"} | O8: =IF(A8="","",IF(AND(COUNTIF(EventTypeList,C8)>0,COUNTIF('Artifact Registry'!$A$5:$A$200,D8)>0,COUNTIF(FamilyList,E8)>0,COUNTIF(NatureList,F8)>0,COUNTIF(LifecycleList,G8)>0,COUNTIF(SignificanceList,L8)>0,COUNTIF(ConsumerList,M8)>0),"PASS","CHECK")) | P8: No | R8: NOTE
A9: EVT-2026-000005 | B9: 2026-06-13 09:00 | C9: ArtifactCreated | D9: PL-STAY-CASE-2026-00001 | E9: Intake & Authorization | F9: Instance | G9: FORM | H9: Property Lead | I9: Internal operating policy | J9: Excel Workbook | K9: v1.0 | L9: Info | M9: Dashboard | N9: {"seed":"Airbnb listing"} | O9: =IF(A9="","",IF(AND(COUNTIF(EventTypeList,C9)>0,COUNTIF('Artifact Registry'!$A$5:$A$200,D9)>0,COUNTIF(FamilyList,E9)>0,COUNTIF(NatureList,F9)>0,COUNTIF(LifecycleList,G9)>0,COUNTIF(SignificanceList,L9)>0,COUNTIF(ConsumerList,M9)>0),"PASS","CHECK")) | P9: No | Q9: CS-2026-01 | R9: FORM
A10: EVT-2026-000006 | B10: 2026-06-14 08:30 | C10: EvidenceGapDetected | D10: PL-STAY-CASE-2026-00002 | E10: Source & Evidence | F10: Instance | G10: DocDump | H10: Property Lead | I10: Internal operating policy | J10: Google Workspace | K10: v1.0 | L10: Critical | M10: Email Alerts | N10: {"missing":"turnover photos","due_by":"2026-06-16"} | O10: =IF(A10="","",IF(AND(COUNTIF(EventTypeList,C10)>0,COUNTIF('Artifact Registry'!$A$5:$A$200,D10)>0,COUNTIF(FamilyList,E10)>0,COUNTIF(NatureList,F10)>0,COUNTIF(LifecycleList,G10)>0,COUNTIF(SignificanceList,L10)>0,COUNTIF(ConsumerList,M10)>0),"PASS","CHECK")) | P10: No | Q10: CS-2026-01 | R10: EVIDENCE
A11: EVT-2026-000007 | B11: 2026-06-13 16:00 | C11: ArtifactApproved | D11: PL-STAY-CASE-2026-00003 | E11: Recommendation & Decision | F11: Instance | G11: CaseSpace | H11: Property Lead | I11: Internal operating policy | J11: Excel Workbook | K11: v1.0 | L11: Action | M11: Audit Log | N11: {"basis":"scope guard"} | O11: =IF(A11="","",IF(AND(COUNTIF(EventTypeList,C11)>0,COUNTIF('Artifact Registry'!$A$5:$A$200,D11)>0,COUNTIF(FamilyList,E11)>0,COUNTIF(NatureList,F11)>0,COUNTIF(LifecycleList,G11)>0,COUNTIF(SignificanceList,L11)>0,COUNTIF(ConsumerList,M11)>0),"PASS","CHECK")) | P11: No | Q11: CS-2026-01 | R11: DECISION
A12: EVT-2026-000008 | B12: 2026-06-28 14:30 | C12: SignalReceived | D12: PL-STAY-CASE-2026-00002 | E12: Source & Evidence | F12: Instance | G12: DocDump | H12: Property Lead | I12: Internal operating policy | J12: Google Workspace | K12: v1.0 | L12: Info | M12: Audit Log | N12: {"connector":"mcp:google-drive","source_ref":"drive:file/9z"} | O12: =IF(A12="","",IF(AND(COUNTIF(EventTypeList,C12)>0,COUNTIF('Artifact Registry'!$A$5:$A$200,D12)>0,COUNTIF(FamilyList,E12)>0,COUNTIF(NatureList,F12)>0,COUNTIF(LifecycleList,G12)>0,COUNTIF(SignificanceList,L12)>0,COUNTIF(ConsumerList,M12)>0),"PASS","CHECK")) | P12: No | Q12: CS-2026-01 | R12: EVIDENCE
A13: EVT-2026-000009 | B13: 2026-06-28 14:31 | C13: SignalHeldForReview | D13: PL-STAY-SIG-2026-00001 | E13: Source & Evidence | F13: Instance | G13: FORM | H13: Property Lead | I13: Internal operating policy | J13: Google Workspace | K13: v1.0 | L13: Watch | M13: Dashboard | N13: {"confidence":0.42,"missing":["reservation_id","guest_email_match","stay_date_match"]} | O13: =IF(A13="","",IF(AND(COUNTIF(EventTypeList,C13)>0,COUNTIF('Artifact Registry'!$A$5:$A$200,D13)>0,COUNTIF(FamilyList,E13)>0,COUNTIF(NatureList,F13)>0,COUNTIF(LifecycleList,G13)>0,COUNTIF(SignificanceList,L13)>0,COUNTIF(ConsumerList,M13)>0),"PASS","CHECK")) | P13: No | R13: NOTE
O14: =IF(A14="","",IF(AND(COUNTIF(EventTypeList,C14)>0,COUNTIF('Artifact Registry'!$A$5:$A$200,D14)>0,COUNTIF(FamilyList,E14)>0,COUNTIF(NatureList,F14)>0,COUNTIF(LifecycleList,G14)>0,COUNTIF(SignificanceList,L14)>0,COUNTIF(ConsumerList,M14)>0),"PASS","CHECK"))
O15: =IF(A15="","",IF(AND(COUNTIF(EventTypeList,C15)>0,COUNTIF('Artifact Registry'!$A$5:$A$200,D15)>0,COUNTIF(FamilyList,E15)>0,COUNTIF(NatureList,F15)>0,COUNTIF(LifecycleList,G15)>0,COUNTIF(SignificanceList,L15)>0,COUNTIF(ConsumerList,M15)>0),"PASS","CHECK"))
O16: =IF(A16="","",IF(AND(COUNTIF(EventTypeList,C16)>0,COUNTIF('Artifact Registry'!$A$5:$A$200,D16)>0,COUNTIF(FamilyList,E16)>0,COUNTIF(NatureList,F16)>0,COUNTIF(LifecycleList,G16)>0,COUNTIF(SignificanceList,L16)>0,COUNTIF(ConsumerList,M16)>0),"PASS","CHECK"))
O17: =IF(A17="","",IF(AND(COUNTIF(EventTypeList,C17)>0,COUNTIF('Artifact Registry'!$A$5:$A$200,D17)>0,COUNTIF(FamilyList,E17)>0,COUNTIF(NatureList,F17)>0,COUNTIF(LifecycleList,G17)>0,COUNTIF(SignificanceList,L17)>0,COUNTIF(ConsumerList,M17)>0),"PASS","CHECK"))
O18: =IF(A18="","",IF(AND(COUNTIF(EventTypeList,C18)>0,COUNTIF('Artifact Registry'!$A$5:$A$200,D18)>0,COUNTIF(FamilyList,E18)>0,COUNTIF(NatureList,F18)>0,COUNTIF(LifecycleList,G18)>0,COUNTIF(SignificanceList,L18)>0,COUNTIF(ConsumerList,M18)>0),"PASS","CHECK"))
O19: =IF(A19="","",IF(AND(COUNTIF(EventTypeList,C19)>0,COUNTIF('Artifact Registry'!$A$5:$A$200,D19)>0,COUNTIF(FamilyList,E19)>0,COUNTIF(NatureList,F19)>0,COUNTIF(LifecycleList,G19)>0,COUNTIF(SignificanceList,L19)>0,COUNTIF(ConsumerList,M19)>0),"PASS","CHECK"))
O20: =IF(A20="","",IF(AND(COUNTIF(EventTypeList,C20)>0,COUNTIF('Artifact Registry'!$A$5:$A$200,D20)>0,COUNTIF(FamilyList,E20)>0,COUNTIF(NatureList,F20)>0,COUNTIF(LifecycleList,G20)>0,COUNTIF(SignificanceList,L20)>0,COUNTIF(ConsumerList,M20)>0),"PASS","CHECK"))
O21: =IF(A21="","",IF(AND(COUNTIF(EventTypeList,C21)>0,COUNTIF('Artifact Registry'!$A$5:$A$200,D21)>0,COUNTIF(FamilyList,E21)>0,COUNTIF(NatureList,F21)>0,COUNTIF(LifecycleList,G21)>0,COUNTIF(SignificanceList,L21)>0,COUNTIF(ConsumerList,M21)>0),"PASS","CHECK"))
O22: =IF(A22="","",IF(AND(COUNTIF(EventTypeList,C22)>0,COUNTIF('Artifact Registry'!$A$5:$A$200,D22)>0,COUNTIF(FamilyList,E22)>0,COUNTIF(NatureList,F22)>0,COUNTIF(LifecycleList,G22)>0,COUNTIF(SignificanceList,L22)>0,COUNTIF(ConsumerList,M22)>0),"PASS","CHECK"))
O23: =IF(A23="","",IF(AND(COUNTIF(EventTypeList,C23)>0,COUNTIF('Artifact Registry'!$A$5:$A$200,D23)>0,COUNTIF(FamilyList,E23)>0,COUNTIF(NatureList,F23)>0,COUNTIF(LifecycleList,G23)>0,COUNTIF(SignificanceList,L23)>0,COUNTIF(ConsumerList,M23)>0),"PASS","CHECK"))
O24: =IF(A24="","",IF(AND(COUNTIF(EventTypeList,C24)>0,COUNTIF('Artifact Registry'!$A$5:$A$200,D24)>0,COUNTIF(FamilyList,E24)>0,COUNTIF(NatureList,F24)>0,COUNTIF(LifecycleList,G24)>0,COUNTIF(SignificanceList,L24)>0,COUNTIF(ConsumerList,M24)>0),"PASS","CHECK"))
O25: =IF(A25="","",IF(AND(COUNTIF(EventTypeList,C25)>0,COUNTIF('Artifact Registry'!$A$5:$A$200,D25)>0,COUNTIF(FamilyList,E25)>0,COUNTIF(NatureList,F25)>0,COUNTIF(LifecycleList,G25)>0,COUNTIF(SignificanceList,L25)>0,COUNTIF(ConsumerList,M25)>0),"PASS","CHECK"))
... O200: =IF(A200="","",IF(AND(COUNTIF(EventTypeList,C200)>0,COUNTIF('Artifact Registry'!$A$5:$A$200,D200)>0,COUNTIF(FamilyList,E200)>0,COUNTIF(NatureList,F200)>0,COUNTIF(LifecycleList,G200)>0,COUNTIF(SignificanceList,L200)>0,COUNTIF(ConsumerList,M200)>0),"PASS","CHECK"))

Sheet Signal Intake
A1: Signal Intake — connector spine
A2: Signal in → governed object → receipt out. PJ places a signal only on evidence. Otherwise it holds it.
A4: Signal ID | B4: Received | C4: Connector | D4: Connector Type | E4: Source Ref | F4: Kind | G4: Artifact ID | H4: Suggested CaseSpace | I4: Confidence | J4: Match Evidence | K4: Missing Evidence | L4: Decision | M4: Receipt ID | N4: Preserved | O4: Checksum | P4: Valid? | Q4: Receipt Verb
A5: SIG-2026-000001 | B5: 46201 | C5: connector:airbnb | D5: api | E5: airbnb:res/HMX8Q2 | F5: row | G5: PL-STAY-CASE-2026-00001 | H5: CS-2026-01 | I5: 0.96 | J5: reservation_id; guest_name; stay_dates | L5: append | M5: RCPT-000001 | N5: Yes | O5: cf1:9a4e… | P5: =IF(A5="","",IF(AND(COUNTIF(ConnectorTypeList,D5)>0,COUNTIF(SignalKindList,F5)>0,COUNTIF(DecisionList,L5)>0,COUNTIF(ReceiptVerbList,Q5)>0,C5<>"",E5<>"",N5="Yes",COUNTIF('Artifact Registry'!$A$5:$A$200,G5)>0,IF(L5="needs_review",AND(K5<>"",Q5="flagged_for_review",I5<ReviewThreshold),AND(I5>=ReviewThreshold,Q5<>"flagged_for_review"))),"PASS","CHECK")) | Q5: appended_to_casespace
A6: SIG-2026-000002 | B6: 46201 | C6: mcp:google-drive | D6: files | E6: drive:file/9z | F6: file | G6: PL-STAY-CASE-2026-00002 | H6: CS-2026-01 | I6: 0.88 | J6: folder_path; reservation_name; stay_dates | L6: append | M6: RCPT-000002 | N6: Yes | O6: cf1:2c77… | P6: =IF(A6="","",IF(AND(COUNTIF(ConnectorTypeList,D6)>0,COUNTIF(SignalKindList,F6)>0,COUNTIF(DecisionList,L6)>0,COUNTIF(ReceiptVerbList,Q6)>0,C6<>"",E6<>"",N6="Yes",COUNTIF('Artifact Registry'!$A$5:$A$200,G6)>0,IF(L6="needs_review",AND(K6<>"",Q6="flagged_for_review",I6<ReviewThreshold),AND(I6>=ReviewThreshold,Q6<>"flagged_for_review"))),"PASS","CHECK")) | Q6: appended_to_casespace
A7: SIG-2026-000003 | B7: 46201 | C7: mcp:gmail | D7: api | E7: gmail:msg/abc123 | F7: email | G7: PL-STAY-SIG-2026-00001 | I7: 0.42 | J7: source:gmail | K7: reservation_id; guest_email_match; stay_date_match | L7: needs_review | M7: RCPT-000003 | N7: Yes | O7: cf1:7ee5… | P7: =IF(A7="","",IF(AND(COUNTIF(ConnectorTypeList,D7)>0,COUNTIF(SignalKindList,F7)>0,COUNTIF(DecisionList,L7)>0,COUNTIF(ReceiptVerbList,Q7)>0,C7<>"",E7<>"",N7="Yes",COUNTIF('Artifact Registry'!$A$5:$A$200,G7)>0,IF(L7="needs_review",AND(K7<>"",Q7="flagged_for_review",I7<ReviewThreshold),AND(I7>=ReviewThreshold,Q7<>"flagged_for_review"))),"PASS","CHECK")) | Q7: flagged_for_review
P8: =IF(A8="","",IF(AND(COUNTIF(ConnectorTypeList,D8)>0,COUNTIF(SignalKindList,F8)>0,COUNTIF(DecisionList,L8)>0,COUNTIF(ReceiptVerbList,Q8)>0,C8<>"",E8<>"",N8="Yes",COUNTIF('Artifact Registry'!$A$5:$A$200,G8)>0,IF(L8="needs_review",AND(K8<>"",Q8="flagged_for_review",I8<ReviewThreshold),AND(I8>=ReviewThreshold,Q8<>"flagged_for_review"))),"PASS","CHECK"))
P9: =IF(A9="","",IF(AND(COUNTIF(ConnectorTypeList,D9)>0,COUNTIF(SignalKindList,F9)>0,COUNTIF(DecisionList,L9)>0,COUNTIF(ReceiptVerbList,Q9)>0,C9<>"",E9<>"",N9="Yes",COUNTIF('Artifact Registry'!$A$5:$A$200,G9)>0,IF(L9="needs_review",AND(K9<>"",Q9="flagged_for_review",I9<ReviewThreshold),AND(I9>=ReviewThreshold,Q9<>"flagged_for_review"))),"PASS","CHECK"))
P10: =IF(A10="","",IF(AND(COUNTIF(ConnectorTypeList,D10)>0,COUNTIF(SignalKindList,F10)>0,COUNTIF(DecisionList,L10)>0,COUNTIF(ReceiptVerbList,Q10)>0,C10<>"",E10<>"",N10="Yes",COUNTIF('Artifact Registry'!$A$5:$A$200,G10)>0,IF(L10="needs_review",AND(K10<>"",Q10="flagged_for_review",I10<ReviewThreshold),AND(I10>=ReviewThreshold,Q10<>"flagged_for_review"))),"PASS","CHECK"))
P11: =IF(A11="","",IF(AND(COUNTIF(ConnectorTypeList,D11)>0,COUNTIF(SignalKindList,F11)>0,COUNTIF(DecisionList,L11)>0,COUNTIF(ReceiptVerbList,Q11)>0,C11<>"",E11<>"",N11="Yes",COUNTIF('Artifact Registry'!$A$5:$A$200,G11)>0,IF(L11="needs_review",AND(K11<>"",Q11="flagged_for_review",I11<ReviewThreshold),AND(I11>=ReviewThreshold,Q11<>"flagged_for_review"))),"PASS","CHECK"))
P12: =IF(A12="","",IF(AND(COUNTIF(ConnectorTypeList,D12)>0,COUNTIF(SignalKindList,F12)>0,COUNTIF(DecisionList,L12)>0,COUNTIF(ReceiptVerbList,Q12)>0,C12<>"",E12<>"",N12="Yes",COUNTIF('Artifact Registry'!$A$5:$A$200,G12)>0,IF(L12="needs_review",AND(K12<>"",Q12="flagged_for_review",I12<ReviewThreshold),AND(I12>=ReviewThreshold,Q12<>"flagged_for_review"))),"PASS","CHECK"))
P13: =IF(A13="","",IF(AND(COUNTIF(ConnectorTypeList,D13)>0,COUNTIF(SignalKindList,F13)>0,COUNTIF(DecisionList,L13)>0,COUNTIF(ReceiptVerbList,Q13)>0,C13<>"",E13<>"",N13="Yes",COUNTIF('Artifact Registry'!$A$5:$A$200,G13)>0,IF(L13="needs_review",AND(K13<>"",Q13="flagged_for_review",I13<ReviewThreshold),AND(I13>=ReviewThreshold,Q13<>"flagged_for_review"))),"PASS","CHECK"))
P14: =IF(A14="","",IF(AND(COUNTIF(ConnectorTypeList,D14)>0,COUNTIF(SignalKindList,F14)>0,COUNTIF(DecisionList,L14)>0,COUNTIF(ReceiptVerbList,Q14)>0,C14<>"",E14<>"",N14="Yes",COUNTIF('Artifact Registry'!$A$5:$A$200,G14)>0,IF(L14="needs_review",AND(K14<>"",Q14="flagged_for_review",I14<ReviewThreshold),AND(I14>=ReviewThreshold,Q14<>"flagged_for_review"))),"PASS","CHECK"))
P15: =IF(A15="","",IF(AND(COUNTIF(ConnectorTypeList,D15)>0,COUNTIF(SignalKindList,F15)>0,COUNTIF(DecisionList,L15)>0,COUNTIF(ReceiptVerbList,Q15)>0,C15<>"",E15<>"",N15="Yes",COUNTIF('Artifact Registry'!$A$5:$A$200,G15)>0,IF(L15="needs_review",AND(K15<>"",Q15="flagged_for_review",I15<ReviewThreshold),AND(I15>=ReviewThreshold,Q15<>"flagged_for_review"))),"PASS","CHECK"))
P16: =IF(A16="","",IF(AND(COUNTIF(ConnectorTypeList,D16)>0,COUNTIF(SignalKindList,F16)>0,COUNTIF(DecisionList,L16)>0,COUNTIF(ReceiptVerbList,Q16)>0,C16<>"",E16<>"",N16="Yes",COUNTIF('Artifact Registry'!$A$5:$A$200,G16)>0,IF(L16="needs_review",AND(K16<>"",Q16="flagged_for_review",I16<ReviewThreshold),AND(I16>=ReviewThreshold,Q16<>"flagged_for_review"))),"PASS","CHECK"))
P17: =IF(A17="","",IF(AND(COUNTIF(ConnectorTypeList,D17)>0,COUNTIF(SignalKindList,F17)>0,COUNTIF(DecisionList,L17)>0,COUNTIF(ReceiptVerbList,Q17)>0,C17<>"",E17<>"",N17="Yes",COUNTIF('Artifact Registry'!$A$5:$A$200,G17)>0,IF(L17="needs_review",AND(K17<>"",Q17="flagged_for_review",I17<ReviewThreshold),AND(I17>=ReviewThreshold,Q17<>"flagged_for_review"))),"PASS","CHECK"))
P18: =IF(A18="","",IF(AND(COUNTIF(ConnectorTypeList,D18)>0,COUNTIF(SignalKindList,F18)>0,COUNTIF(DecisionList,L18)>0,COUNTIF(ReceiptVerbList,Q18)>0,C18<>"",E18<>"",N18="Yes",COUNTIF('Artifact Registry'!$A$5:$A$200,G18)>0,IF(L18="needs_review",AND(K18<>"",Q18="flagged_for_review",I18<ReviewThreshold),AND(I18>=ReviewThreshold,Q18<>"flagged_for_review"))),"PASS","CHECK"))
P19: =IF(A19="","",IF(AND(COUNTIF(ConnectorTypeList,D19)>0,COUNTIF(SignalKindList,F19)>0,COUNTIF(DecisionList,L19)>0,COUNTIF(ReceiptVerbList,Q19)>0,C19<>"",E19<>"",N19="Yes",COUNTIF('Artifact Registry'!$A$5:$A$200,G19)>0,IF(L19="needs_review",AND(K19<>"",Q19="flagged_for_review",I19<ReviewThreshold),AND(I19>=ReviewThreshold,Q19<>"flagged_for_review"))),"PASS","CHECK"))
... P60: =IF(A60="","",IF(AND(COUNTIF(ConnectorTypeList,D60)>0,COUNTIF(SignalKindList,F60)>0,COUNTIF(DecisionList,L60)>0,COUNTIF(ReceiptVerbList,Q60)>0,C60<>"",E60<>"",N60="Yes",COUNTIF('Artifact Registry'!$A$5:$A$200,G60)>0,IF(L60="needs_review",AND(K60<>"",Q60="flagged_for_review",I60<ReviewThreshold),AND(I60>=ReviewThreshold,Q60<>"flagged_for_review"))),"PASS","CHECK"))
A63: A held signal must carry Missing Evidence, the verb flagged_for_review, and confidence below REVIEW_THRESHOLD (Control!B55, mirrored from golden-path/src/connector.js). A placed signal must be at or above threshold. Valid? enforces all three.

Sheet Review Queue
A1: Review Queue — PJ did not guess
A2: A held signal is resolved by a person. The resolution emits a second receipt linked to the first.
A4: Review ID | B4: Signal ID | C4: Prior Receipt ID | D4: Artifact ID | E4: Held reason | F4: Missing evidence | G4: Resolution | H4: Case ID | I4: Resolved by (role) | J4: Resolution reason | K4: Resolved date | L4: Second Receipt ID | M4: Status | N4: Second Receipt Verb
A5: REV-000001 | B5: SIG-2026-000003 | C5: RCPT-000003 | D5: PL-STAY-SIG-2026-00001 | E5: No thread hint, reservation ID, guest email match, or date match found | F5: reservation_id; guest_email_match; stay_date_match | M5: =IF(A5="","",IF(AND(G5<>"",I5<>"",L5<>"",N5<>""),"Resolved","Open"))
M6: =IF(A6="","",IF(AND(G6<>"",I6<>"",L6<>"",N6<>""),"Resolved","Open"))
M7: =IF(A7="","",IF(AND(G7<>"",I7<>"",L7<>"",N7<>""),"Resolved","Open"))
M8: =IF(A8="","",IF(AND(G8<>"",I8<>"",L8<>"",N8<>""),"Resolved","Open"))
M9: =IF(A9="","",IF(AND(G9<>"",I9<>"",L9<>"",N9<>""),"Resolved","Open"))
M10: =IF(A10="","",IF(AND(G10<>"",I10<>"",L10<>"",N10<>""),"Resolved","Open"))
M11: =IF(A11="","",IF(AND(G11<>"",I11<>"",L11<>"",N11<>""),"Resolved","Open"))
M12: =IF(A12="","",IF(AND(G12<>"",I12<>"",L12<>"",N12<>""),"Resolved","Open"))
M13: =IF(A13="","",IF(AND(G13<>"",I13<>"",L13<>"",N13<>""),"Resolved","Open"))
M14: =IF(A14="","",IF(AND(G14<>"",I14<>"",L14<>"",N14<>""),"Resolved","Open"))
M15: =IF(A15="","",IF(AND(G15<>"",I15<>"",L15<>"",N15<>""),"Resolved","Open"))
M16: =IF(A16="","",IF(AND(G16<>"",I16<>"",L16<>"",N16<>""),"Resolved","Open"))
M17: =IF(A17="","",IF(AND(G17<>"",I17<>"",L17<>"",N17<>""),"Resolved","Open"))
... M40: =IF(A40="","",IF(AND(G40<>"",I40<>"",L40<>"",N40<>""),"Resolved","Open"))
A43: Resolving an item requires Resolution, Resolved by, and a Second Receipt ID. Then log a SignalResolved event citing the prior receipt. Never overwrite the first receipt.

Sheet Sources
A1: Sources
A2: Systems of record own truth. PJ observes changes and normalizes event facts.
A4: Source System | B4: Owns Truth For | C4: Observed Changes | D4: Identity Delegated? | E4: PJ Writes Back? | F4: Adapter Notes
A5: Excel Workbook | B5: Taxonomy, module registry, trackers | C5: Cell/row status changes; artifact metadata updates | D5: Yes | E5: No | F5: Best for small towns and fast prototyping.
A6: GitHub | B6: Code, specs, doctrine, versioned text | C6: Commit, PR, issue, release, file changes | D6: Yes | E6: No | F6: Supports PuddleJumper canon and product development.
A7: Google Workspace | B7: Docs, Sheets, Drive evidence | C7: File created/modified/shared/approved | D7: Yes | E7: No | F7: Can watch Drive metadata and document lifecycle events.
A8: Microsoft 365 | B8: SharePoint, Teams, Outlook records | C8: Document status, emails, approvals, file moves | D8: Yes | E8: No | F8: Likely municipal enterprise identity backbone.
A9: CivicPlus | B9: Municipal web content and public pages | C9: Public record publication, page update, file upload | D9: Yes | E9: No | F9: PJ observes public-facing governance signals.
A10: CaseSpace | B10: Active work context | C10: Task transitions, owner changes, evidence gaps | D10: Yes | E10: Optional adapter | F10: CaseSpace can subscribe to PJ and also publish events.
A11: ARCHIEVE | B11: Final record/memory layer | C11: Snapshot created, retention event, transfer packet | D11: Yes | E11: Optional adapter | F11: ARCHIEVE is memory; PJ is observation.

Sheet Consumers
A1: Consumers
A2: Subscribers decide behavior. PJ publishes governed facts; consumers act independently.
A4: Consumer | B4: Consumes Events | C4: Action Owned By Consumer | D4: Default Channel | E4: Criticality | F4: Notes
A5: CaseSpace | B5: LifecycleAdvanced, ArtifactTransferred, EvidenceGapDetected | C5: Update work item/status/owner | D5: Internal workspace | E5: High | F5: Operational work remains in CaseSpace.
A6: ARCHIEVE | B6: ArtifactArchived, ArtifactIssued, RetentionTriggered | C6: Index record, preserve snapshot, start retention | D6: Archive ledger | E6: High | F6: Memory and recordkeeping are separate from PJ.
A7: Email Alerts | B7: ArtifactApproved, ArtifactIssued, EvidenceGapDetected, AuthorityChanged | C7: Notify named role(s) | D7: Email | E7: Medium | F7: Human alerting is a subscriber behavior, not PJ core logic.
A8: Slack/Teams | B8: ModuleReady, LifecycleAdvanced, EvidenceGapDetected | C8: Post concise operational signal | D8: Teams/Slack | E8: Medium | F8: Optional collaboration adapter.
